Workbook

Sheet 🔐 SHA-1
B1: 🔐 SHA-1 — pure Excel formulas, no VBA
B2: 32-bit words · Big-endian · 80 rounds · 4 constants · Excel 2013+
B4: ✏️ ENTER A WORD (1–7 ASCII characters):
B5: hello
B7: 🔑 SHA-1 RESULT:
B8: ='⚙️ Computation'!B2 -> aaf4c61ddcc5e8a2dabede0f3b482cd9aea9434d
B10: 📌 Sheets: 📖 How SHA-1 Works | 📦 Константы | ⚙️ Computation
B12: ✅ Verified: "hello" → aaf4c61ddcc5e8a2dabede0f3b482cd9aea9434d
B13: ⚠️ Maximum 7 characters · ASCII only · SHA-1 считается устаревшим с 2017 года

Sheet 📖 How SHA-1 Works
B1: 📖 How SHA-1 Works — step-by-step explanation
B2: SHA-1 Overview
B3: SHA-1 — хэш-функция NIST (1995), пришедшая на смену MD5. Блок: 512 бит (64 байта). Хэш: 160 бит (40 hex символов). 5 переменных состояния (a,b,c,d,e). 80 раундов. 4 константы K. ⚠️ Считается криптографически слабым с 2017 года (SHAttered атака).
B4: Comparison with MD5
B5: MD5: 4 переменные, 64 раунда, little-endian, 128-бит хэш SHA-1: 5 переменных, 80 раундов, big-endian, 160-бит хэш Главные отличия: · SHA-1 использует ROL (левый циклический сдвиг), MD5 — смешанные сдвиги · SHA-1: расписание W[i] через XOR+ROL, MD5: прямые слова M[i] · SHA-1 big-endian (как SHA-256), MD5 little-endian
B6: Padding
B7: Идентично SHA-256: · Добавить байт 0x80 после сообщения · Добавлять нули до длины ≡ 56 (mod 64) · Байты 56..63: исходная длина в битах (big-endian 64-bit) Для ≤7 байт: итого ровно 512 бит = 16 слов W[0..15].
B8: Initial Constants H[0..4]
B9: 5 магических 32-битных чисел (из стандарта FIPS 180): H0 = 0x67452301 (те же что в MD5!) H1 = 0xEFCDAB89 H2 = 0x98BADCFE H3 = 0x10325476 H4 = 0xC3D2E1F0 ← новый, которого нет в MD5
B10: Message Schedule W[0..79]
B11: W[0..15] = 16 слов из входного блока (big-endian 32-bit). W[i] для i=16..79: W[i] = ROL32( W[i-3] XOR W[i-8] XOR W[i-14] XOR W[i-16], 1 ) В Excel: XOR через a+b-2×AND(a,b), ROL через MOD/INT. Промежуточный XOR хранится в helper-ячейке, затем ROL.
B12: 4 Rounds of 20 Operations
... B17: · ROL32(x,n) = MOD( MOD(x,2^(32−n))×2^n + INT(x/2^(32−n)), 2³² ) · XOR32(a,b) через AND32 (побайтовое INT/MOD разложение) · Ch = AND(b,c) + AND(NOT_b,d) [биты попарно непересекаются] · Parity = XOR3(b,c,d) = b+c-2AND(b,c), затем XOR с d · Maj = AND(b,c)+AND(b,d)+AND(c,d)-2×AND(AND(b,c),AND(c,d)) · Каждый W[i>=16] хранит промежуточный XOR в helper-ячейке · Итого ~1500 формул на 3 листа

Sheet 📦 SHA-1 Constants
B1: 📦 SHA-1 Constants: K[0..3] and H[0..4]
B2: K[i] is used in each of 4 blocks of 20 operations. H[0..4] — initial state values (same as MD5 for H[0..3]).
B3: Round | C3: K (decimal) | D3: K (hex) | E3: Operations | G3: Initial H[0..4]
B4: Round 1 (0–19) | C4: 1518500249 | D4: 0x5A827999 | E4: Ch (f=AND+AND) | G4: H0 = 1732584193 | H4: 0x67452301 | I4: √2 (×2³²)
B5: Round 2 (20–39) | C5: 1859775393 | D5: 0x6ED9EBA1 | E5: Parity (f=XOR) | G5: H1 = 4023233417 | H5: 0xEFCDAB89 | I5: √3
B6: Round 3 (40–59) | C6: 2400959708 | D6: 0x8F1BBCDC | E6: Maj (f=AND×3) | G6: H2 = 2562383102 | H6: 0x98BADCFE | I6: √5
B7: Round 4 (60–79) | C7: 3395469782 | D7: 0xCA62C1D6 | E7: Parity (f=XOR) | G7: H3 = 271733878 | H7: 0x10325476 | I7: √7
G8: H4 = 3285377520 | H8: 0xC3D2E1F0 | I8: √11

Sheet ⚙️ Computation
B1: ⚙️ SHA-1 Computation — 80 rounds (a,b,c,d,e + helper columns)
B2: =LOWER(MID("0123456789abcdef",MOD(INT((MOD(INT(C86/256^3),256))/16),16)+1,1)&MID("0123456789abcdef",MOD(MOD((MOD(INT(C86/256^3),256)),16),16)+1,1)&MID("0123456789abcdef",MOD(INT((MOD(INT(C86/256^2),256))/16),16)+1,1)&MID("0123456789abcdef",MOD(MOD((MOD(INT(C86/256^2),256)),16),16)+1,1)&MID("0123456789abcdef",MOD(INT((MOD(INT(C86/256^1),256))/16),16)+1,1)&MID("0123456789abcdef",MOD(MOD((MOD(INT(C86/256^1),256)),16),16)+1,1)&MID("0123456789abcdef",MOD(INT((MOD(INT(C86/256^0),256))/16),16)+1,1)&MID("0123456789abcdef",MOD(MOD((MOD(INT(C86/256^0),256)),16),16)+1,1)&MID("0123456789abcdef",MOD(INT((MOD(INT(D86/256^3),256))/16),16)+1,1)&MID("0123456789abcdef",MOD(MOD((MOD(INT(D86/256^3),256)),16),16)+1,1)&MID("0123456789abcdef",MOD(INT((MOD(INT(D86/256^2),256))/16),16)+1,1)&MID("0123456789abcdef",MOD(MOD((MOD(INT(D86/256^2),256)),16),16)+1,1)&MID("0123456789abcdef",MOD(INT((MOD(INT(D86/256^1),256))/16),16)+1,1)&MID("0123456789abcdef",MOD(MOD((MOD(INT(D86/256^1),256)),16),16)+1,1)&MID("0123456789abcdef",MOD(INT((MOD(INT(D86/256^0),256))/16),16)+1,1)&MID("0123456789abcdef",MOD(MOD((MOD(INT(D86/256^0),256)),16),16)+1,1)&MID("0123456789abcdef",MOD(INT((MOD(INT(E86/256^3),256))/16),16)+1,1)&MID("0123456789abcdef",MOD(MOD((MOD(INT(E86/256^3),256)),16),16)+1,1)&MID("0123456789abcdef",MOD(INT((MOD(INT(E86/256^2),256))/16),16)+1,1)&MID("0123456789abcdef",MOD(MOD((MOD(INT(E86/256^2),256)),16),16)+1,1)&MID("0123456789abcdef",MOD(INT((MOD(INT(E86/256^1),256))/16),16)+1,1)&MID("0123456789abcdef",MOD(MOD((MOD(INT(E86/256^1),256)),16),16)+1,1)&MID("0123456789abcdef",MOD(INT((MOD(INT(E86/256^0),256))/16),16)+1,1)&MID("0123456789abcdef",MOD(MOD((MOD(INT(E86/256^0),256)),16),16)+1,1)&MID("0123456789abcdef",MOD(INT((MOD(INT(F86/256^3),256))/16),16)+1,1)&MID("0123456789abcdef",MOD(MOD((MOD(INT(F86/256^3),256)),16),16)+1,1)&MID("0123456789abcdef",MOD(INT((MOD(INT(F86/256^2),256))/16),16)+1,1)&MID("0123456789abcdef",MOD(MOD((MOD(INT(F86/256^2),256)),16),16)+1,1)&MID("0123456789abcdef",MOD(INT((MOD(INT(F86/256^1),256))/16),16)+1,1)&MID("0123456789abcdef",MOD(MOD((MOD(INT(F86/256^1),256)),16),16)+1,1)&MID("0123456789abcdef",MOD(INT((MOD(INT(F86/256^0),256))/16),16)+1,1)&MID("0123456789abcdef",MOD(MOD((MOD(INT(F86/256^0),256)),16),16)+1,1)&MID("0123456789abcdef",MOD(INT((MOD(INT(G86/256^3),256))/16),16)+1,1)&MID("0123456789abcdef",MOD(MOD((MOD(INT(G86/256^3),256)),16),16)+1,1)&MID("0123456789abcdef",MOD(INT((MOD(INT(G86/256^2),256))/16),16)+1,1)&MID("0123456789abcdef",MOD(MOD((MOD(INT(G86/256^2),256)),16),16)+1,1)&MID("0123456789abcdef",MOD(INT((MOD(INT(G86/256^1),256))/16),16)+1,1)&MID("0123456789abcdef",MOD(MOD((MOD(INT(G86/256^1),256)),16),16)+1,1)&MID("0123456789abcdef",MOD(INT((MOD(INT(G86/256^0),256))/16),16)+1,1)&MID("0123456789abcdef",MOD(MOD((MOD(INT(G86/256^0),256)),16),16)+1,1)) -> aaf4c61ddcc5e8a2dabede0f3b482cd9aea9434d
B3: Each step: tmp=ADD32(ROL(a,5), f(b,c,d), e, K, W[i]) e←d d←c c←ROL(b,30) b←a a←tmp | Round 1: f=Ch Round 2: f=XOR Round 3: f=Maj Round 4: f=XOR
B4: Step | C4: a | D4: b | E4: c | F4: d | G4: e | H4: ROL(a,5) | I4: f_part1 | J4: f_part2 | K4: AND(fp1,fp2) | L4: f | M4: AND(f,W_k) | N4: tmp_inner | O4: tmp=new_a | P4: ROL(b,30) | BF4: W[i]
B5: INIT | C5: 1732584193 | D5: 4023233417 | E5: 2562383102 | F5: 271733878 | G5: 3285377520
B6: 1 | C6: =MOD(H6+L6+G5+1518500249+BF200,4294967296) -> 135922975 | D6: =C5 -> 1732584193 | E6: =P6 -> 2079550178 | F6: =E5 -> 2562383102 | G6: =F5 -> 271733878 | H6: =MOD(MOD(C5,2^27)*2^5+INT(C5/2^27),4294967296) -> 3903086636 | I6: =((MOD(INT(MOD(INT((D5)/1),256)/2^0),2)*MOD(INT(MOD(INT((E5)/1),256)/2^0),2)*1+MOD(INT(MOD(INT((D5)/1),256)/2^1),2)*MOD(INT(MOD(INT((E5)/1),256)/2^1),2)*2+MOD(INT(MOD(INT((D5)/1),256)/2^2),2)*MOD(INT(MOD(INT((E5)/1),256)/2^2),2)*4+MOD(INT(MOD(INT((D5)/1),256)/2^3),2)*MOD(INT(MOD(INT((E5)/1),256)/2^3),2)*8+MOD(INT(MOD(INT((D5)/1),256)/2^4),2)*MOD(INT(MOD(INT((E5)/1),256)/2^4),2)*16+MOD(INT(MOD(INT((D5)/1),256)/2^5),2)*MOD(INT(MOD(INT((E5)/1),256)/2^5),2)*32+MOD(INT(MOD(INT((D5)/1),256)/2^6),2)*MOD(INT(MOD(INT((E5)/1),256)/2^6),2)*64+MOD(INT(MOD(INT((D5)/1),256)/2^7),2)*MOD(INT(MOD(INT((E5)/1),256)/2^7),2)*128)*1+(MOD(INT(MOD(INT((D5)/256),256)/2^0),2)*MOD(INT(MOD(INT((E5)/256),256)/2^0),2)*1+MOD(INT(MOD(INT((D5)/256),256)/2^1),2)*MOD(INT(MOD(INT((E5)/256),256)/2^1),2)*2+MOD(INT(MOD(INT((D5)/256),256)/2^2),2)*MOD(INT(MOD(INT((E5)/256),256)/2^2),2)*4+MOD(INT(MOD(INT((D5)/256),256)/2^3),2)*MOD(INT(MOD(INT((E5)/256),256)/2^3),2)*8+MOD(INT(MOD(INT((D5)/256),256)/2^4),2)*MOD(INT(MOD(INT((E5)/256),256)/2^4),2)*16+MOD(INT(MOD(INT((D5)/256),256)/2^5),2)*MOD(INT(MOD(INT((E5)/256),256)/2^5),2)*32+MOD(INT(MOD(INT((D5)/256),256)/2^6),2)*MOD(INT(MOD(INT((E5)/256),256)/2^6),2)*64+MOD(INT(MOD(INT((D5)/256),256)/2^7),2)*MOD(INT(MOD(INT((E5)/256),256)/2^7),2)*128)*256+(MOD(INT(MOD(INT((D5)/65536),256)/2^0),2)*MOD(INT(MOD(INT((E5)/65536),256)/2^0),2)*1+MOD(INT(MOD(INT((D5)/65536),256)/2^1),2)*MOD(INT(MOD(INT((E5)/65536),256)/2^1),2)*2+MOD(INT(MOD(INT((D5)/65536),256)/2^2),2)*MOD(INT(MOD(INT((E5)/65536),256)/2^2),2)*4+MOD(INT(MOD(INT((D5)/65536),256)/2^3),2)*MOD(INT(MOD(INT((E5)/65536),256)/2^3),2)*8+MOD(INT(MOD(INT((D5)/65536),256)/2^4),2)*MOD(INT(MOD(INT((E5)/65536),256)/2^4),2)*16+MOD(INT(MOD(INT((D5)/65536),256)/2^5),2)*MOD(INT(MOD(INT((E5)/65536),256)/2^5),2)*32+MOD(INT(MOD(INT((D5)/65536),256)/2^6),2)*MOD(INT(MOD(INT((E5)/65536),256)/2^6),2)*64+MOD(INT(MOD(INT((D5)/65536),256)/2^7),2)*MOD(INT(MOD(INT((E5)/65536),256)/2^7),2)*128)*65536+(MOD(INT(MOD(INT((D5)/16777216),256)/2^0),2)*MOD(INT(MOD(INT((E5)/16777216),256)/2^0),2)*1+MOD(INT(MOD(INT((D5)/16777216),256)/2^1),2)*MOD(INT(MOD(INT((E5)/16777216),256)/2^1),2)*2+MOD(INT(MOD(INT((D5)/16777216),256)/2^2),2)*MOD(INT(MOD(INT((E5)/16777216),256)/2^2),2)*4+MOD(INT(MOD(INT((D5)/16777216),256)/2^3),2)*MOD(INT(MOD(INT((E5)/16777216),256)/2^3),2)*8+MOD(INT(MOD(INT((D5)/16777216),256)/2^4),2)*MOD(INT(MOD(INT((E5)/16777216),256)/2^4),2)*16+MOD(INT(MOD(INT((D5)/16777216),256)/2^5),2)*MOD(INT(MOD(INT((E5)/16777216),256)/2^5),2)*32+MOD(INT(MOD(INT((D5)/16777216),256)/2^6),2)*MOD(INT(MOD(INT((E5)/16777216),256)/2^6),2)*64+MOD(INT(MOD(INT((D5)/16777216),256)/2^7),2)*MOD(INT(MOD(INT((E5)/16777216),256)/2^7),2)*128)*16777216) -> 2290649224 | J6: =((MOD(INT(MOD(INT(((4294967295-D5))/1),256)/2^0),2)*MOD(INT(MOD(INT((F5)/1),256)/2^0),2)*1+MOD(INT(MOD(INT(((4294967295-D5))/1),256)/2^1),2)*MOD(INT(MOD(INT((F5)/1),256)/2^1),2)*2+MOD(INT(MOD(INT(((4294967295-D5))/1),256)/2^2),2)*MOD(INT(MOD(INT((F5)/1),256)/2^2),2)*4+MOD(INT(MOD(INT(((4294967295-D5))/1),256)/2^3),2)*MOD(INT(MOD(INT((F5)/1),256)/2^3),2)*8+MOD(INT(MOD(INT(((4294967295-D5))/1),256)/2^4),2)*MOD(INT(MOD(INT((F5)/1),256)/2^4),2)*16+MOD(INT(MOD(INT(((4294967295-D5))/1),256)/2^5),2)*MOD(INT(MOD(INT((F5)/1),256)/2^5),2)*32+MOD(INT(MOD(INT(((4294967295-D5))/1),256)/2^6),2)*MOD(INT(MOD(INT((F5)/1),256)/2^6),2)*64+MOD(INT(MOD(INT(((4294967295-D5))/1),256)/2^7),2)*MOD(INT(MOD(INT((F5)/1),256)/2^7),2)*128)*1+(MOD(INT(MOD(INT(((4294967295-D5))/256),256)/2^0),2)*MOD(INT(MOD(INT((F5)/256),256)/2^0),2)*1+MOD(INT(MOD(INT(((4294967295-D5))/256),256)/2^1),2)*MOD(INT(MOD(INT((F5)/256),256)/2^1),2)*2+MOD(INT(MOD(INT(((4294967295-D5))/256),256)/2^2),2)*MOD(INT(MOD(INT((F5)/256),256)/2^2),2)*4+MOD(INT(MOD(INT(((4294967295-D5))/256),256)/2^3),2)*MOD(INT(MOD(INT((F5)/256),256)/2^3),2)*8+MOD(INT(MOD(INT(((4294967295-D5))/256),256)/2^4),2)*MOD(INT(MOD(INT((F5)/256),256)/2^4),2)*16+MOD(INT(MOD(INT(((4294967295-D5))/256),256)/2^5),2)*MOD(INT(MOD(INT((F5)/256),256)/2^5),2)*32+MOD(INT(MOD(INT(((4294967295-D5))/256),256)/2^6),2)*MOD(INT(MOD(INT((F5)/256),256)/2^6),2)*64+MOD(INT(MOD(INT(((4294967295-D5))/256),256)/2^7),2)*MOD(INT(MOD(INT((F5)/256),256)/2^7),2)*128)*256+(MOD(INT(MOD(INT(((4294967295-D5))/65536),256)/2^0),2)*MOD(INT(MOD(INT((F5)/65536),256)/2^0),2)*1+MOD(INT(MOD(INT(((4294967295-D5))/65536),256)/2^1),2)*MOD(INT(MOD(INT((F5)/65536),256)/2^1),2)*2+MOD(INT(MOD(INT(((4294967295-D5))/65536),256)/2^2),2)*MOD(INT(MOD(INT((F5)/65536),256)/2^2),2)*4+MOD(INT(MOD(INT(((4294967295-D5))/65536),256)/2^3),2)*MOD(INT(MOD(INT((F5)/65536),256)/2^3),2)*8+MOD(INT(MOD(INT(((4294967295-D5))/65536),256)/2^4),2)*MOD(INT(MOD(INT((F5)/65536),256)/2^4),2)*16+MOD(INT(MOD(INT(((4294967295-D5))/65536),256)/2^5),2)*MOD(INT(MOD(INT((F5)/65536),256)/2^5),2)*32+MOD(INT(MOD(INT(((4294967295-D5))/65536),256)/2^6),2)*MOD(INT(MOD(INT((F5)/65536),256)/2^6),2)*64+MOD(INT(MOD(INT(((4294967295-D5))/65536),256)/2^7),2)*MOD(INT(MOD(INT((F5)/65536),256)/2^7),2)*128)*65536+(MOD(INT(MOD(INT(((4294967295-D5))/16777216),256)/2^0),2)*MOD(INT(MOD(INT((F5)/16777216),256)/2^0),2)*1+MOD(INT(MOD(INT(((4294967295-D5))/16777216),256)/2^1),2)*MOD(INT(MOD(INT((F5)/16777216),256)/2^1),2)*2+MOD(INT(MOD(INT(((4294967295-D5))/16777216),256)/2^2),2)*MOD(INT(MOD(INT((F5)/16777216),256)/2^2),2)*4+MOD(INT(MOD(INT(((4294967295-D5))/16777216),256)/2^3),2)*MOD(INT(MOD(INT((F5)/16777216),256)/2^3),2)*8+MOD(INT(MOD(INT(((4294967295-D5))/16777216),256)/2^4),2)*MOD(INT(MOD(INT((F5)/16777216),256)/2^4),2)*16+MOD(INT(MOD(INT(((4294967295-D5))/16777216),256)/2^5),2)*MOD(INT(MOD(INT((F5)/16777216),256)/2^5),2)*32+MOD(INT(MOD(INT(((4294967295-D5))/16777216),256)/2^6),2)*MOD(INT(MOD(INT((F5)/16777216),256)/2^6),2)*64+MOD(INT(MOD(INT(((4294967295-D5))/16777216),256)/2^7),2)*MOD(INT(MOD(INT((F5)/16777216),256)/2^7),2)*128)*16777216) -> 271733878 | K6: =0 -> 0 | L6: =MOD(I6+J6,4294967296) -> 2562383102 | P6: =MOD(MOD(D5,2^2)*2^30+INT(D5/2^2),4294967296) -> 2079550178
B7: 2 | C7: =MOD(H7+L7+G6+1518500249+BF201,4294967296) -> 3648090350 | D7: =C6 -> 135922975 | E7: =P7 -> 1506887872 | F7: =E6 -> 2079550178 | G7: =F6 -> 2562383102 | H7: =MOD(MOD(C6,2^27)*2^5+INT(C6/2^27),4294967296) -> 54567905 | I7: =((MOD(INT(MOD(INT((D6)/1),256)/2^0),2)*MOD(INT(MOD(INT((E6)/1),256)/2^0),2)*1+MOD(INT(MOD(INT((D6)/1),256)/2^1),2)*MOD(INT(MOD(INT((E6)/1),256)/2^1),2)*2+MOD(INT(MOD(INT((D6)/1),256)/2^2),2)*MOD(INT(MOD(INT((E6)/1),256)/2^2),2)*4+MOD(INT(MOD(INT((D6)/1),256)/2^3),2)*MOD(INT(MOD(INT((E6)/1),256)/2^3),2)*8+MOD(INT(MOD(INT((D6)/1),256)/2^4),2)*MOD(INT(MOD(INT((E6)/1),256)/2^4),2)*16+MOD(INT(MOD(INT((D6)/1),256)/2^5),2)*MOD(INT(MOD(INT((E6)/1),256)/2^5),2)*32+MOD(INT(MOD(INT((D6)/1),256)/2^6),2)*MOD(INT(MOD(INT((E6)/1),256)/2^6),2)*64+MOD(INT(MOD(INT((D6)/1),256)/2^7),2)*MOD(INT(MOD(INT((E6)/1),256)/2^7),2)*128)*1+(MOD(INT(MOD(INT((D6)/256),256)/2^0),2)*MOD(INT(MOD(INT((E6)/256),256)/2^0),2)*1+MOD(INT(MOD(INT((D6)/256),256)/2^1),2)*MOD(INT(MOD(INT((E6)/256),256)/2^1),2)*2+MOD(INT(MOD(INT((D6)/256),256)/2^2),2)*MOD(INT(MOD(INT((E6)/256),256)/2^2),2)*4+MOD(INT(MOD(INT((D6)/256),256)/2^3),2)*MOD(INT(MOD(INT((E6)/256),256)/2^3),2)*8+MOD(INT(MOD(INT((D6)/256),256)/2^4),2)*MOD(INT(MOD(INT((E6)/256),256)/2^4),2)*16+MOD(INT(MOD(INT((D6)/256),256)/2^5),2)*MOD(INT(MOD(INT((E6)/256),256)/2^5),2)*32+MOD(INT(MOD(INT((D6)/256),256)/2^6),2)*MOD(INT(MOD(INT((E6)/256),256)/2^6),2)*64+MOD(INT(MOD(INT((D6)/256),256)/2^7),2)*MOD(INT(MOD(INT((E6)/256),256)/2^7),2)*128)*256+(MOD(INT(MOD(INT((D6)/65536),256)/2^0),2)*MOD(INT(MOD(INT((E6)/65536),256)/2^0),2)*1+MOD(INT(MOD(INT((D6)/65536),256)/2^1),2)*MOD(INT(MOD(INT((E6)/65536),256)/2^1),2)*2+MOD(INT(MOD(INT((D6)/65536),256)/2^2),2)*MOD(INT(MOD(INT((E6)/65536),256)/2^2),2)*4+MOD(INT(MOD(INT((D6)/65536),256)/2^3),2)*MOD(INT(MOD(INT((E6)/65536),256)/2^3),2)*8+MOD(INT(MOD(INT((D6)/65536),256)/2^4),2)*MOD(INT(MOD(INT((E6)/65536),256)/2^4),2)*16+MOD(INT(MOD(INT((D6)/65536),256)/2^5),2)*MOD(INT(MOD(INT((E6)/65536),256)/2^5),2)*32+MOD(INT(MOD(INT((D6)/65536),256)/2^6),2)*MOD(INT(MOD(INT((E6)/65536),256)/2^6),2)*64+MOD(INT(MOD(INT((D6)/65536),256)/2^7),2)*MOD(INT(MOD(INT((E6)/65536),256)/2^7),2)*128)*65536+(MOD(INT(MOD(INT((D6)/16777216),256)/2^0),2)*MOD(INT(MOD(INT((E6)/16777216),256)/2^0),2)*1+MOD(INT(MOD(INT((D6)/16777216),256)/2^1),2)*MOD(INT(MOD(INT((E6)/16777216),256)/2^1),2)*2+MOD(INT(MOD(INT((D6)/16777216),256)/2^2),2)*MOD(INT(MOD(INT((E6)/16777216),256)/2^2),2)*4+MOD(INT(MOD(INT((D6)/16777216),256)/2^3),2)*MOD(INT(MOD(INT((E6)/16777216),256)/2^3),2)*8+MOD(INT(MOD(INT((D6)/16777216),256)/2^4),2)*MOD(INT(MOD(INT((E6)/16777216),256)/2^4),2)*16+MOD(INT(MOD(INT((D6)/16777216),256)/2^5),2)*MOD(INT(MOD(INT((E6)/16777216),256)/2^5),2)*32+MOD(INT(MOD(INT((D6)/16777216),256)/2^6),2)*MOD(INT(MOD(INT((E6)/16777216),256)/2^6),2)*64+MOD(INT(MOD(INT((D6)/16777216),256)/2^7),2)*MOD(INT(MOD(INT((E6)/16777216),256)/2^7),2)*128)*16777216) -> 1665212928 | J7: =((MOD(INT(MOD(INT(((4294967295-D6))/1),256)/2^0),2)*MOD(INT(MOD(INT((F6)/1),256)/2^0),2)*1+MOD(INT(MOD(INT(((4294967295-D6))/1),256)/2^1),2)*MOD(INT(MOD(INT((F6)/1),256)/2^1),2)*2+MOD(INT(MOD(INT(((4294967295-D6))/1),256)/2^2),2)*MOD(INT(MOD(INT((F6)/1),256)/2^2),2)*4+MOD(INT(MOD(INT(((4294967295-D6))/1),256)/2^3),2)*MOD(INT(MOD(INT((F6)/1),256)/2^3),2)*8+MOD(INT(MOD(INT(((4294967295-D6))/1),256)/2^4),2)*MOD(INT(MOD(INT((F6)/1),256)/2^4),2)*16+MOD(INT(MOD(INT(((4294967295-D6))/1),256)/2^5),2)*MOD(INT(MOD(INT((F6)/1),256)/2^5),2)*32+MOD(INT(MOD(INT(((4294967295-D6))/1),256)/2^6),2)*MOD(INT(MOD(INT((F6)/1),256)/2^6),2)*64+MOD(INT(MOD(INT(((4294967295-D6))/1),256)/2^7),2)*MOD(INT(MOD(INT((F6)/1),256)/2^7),2)*128)*1+(MOD(INT(MOD(INT(((4294967295-D6))/256),256)/2^0),2)*MOD(INT(MOD(INT((F6)/256),256)/2^0),2)*1+MOD(INT(MOD(INT(((4294967295-D6))/256),256)/2^1),2)*MOD(INT(MOD(INT((F6)/256),256)/2^1),2)*2+MOD(INT(MOD(INT(((4294967295-D6))/256),256)/2^2),2)*MOD(INT(MOD(INT((F6)/256),256)/2^2),2)*4+MOD(INT(MOD(INT(((4294967295-D6))/256),256)/2^3),2)*MOD(INT(MOD(INT((F6)/256),256)/2^3),2)*8+MOD(INT(MOD(INT(((4294967295-D6))/256),256)/2^4),2)*MOD(INT(MOD(INT((F6)/256),256)/2^4),2)*16+MOD(INT(MOD(INT(((4294967295-D6))/256),256)/2^5),2)*MOD(INT(MOD(INT((F6)/256),256)/2^5),2)*32+MOD(INT(MOD(INT(((4294967295-D6))/256),256)/2^6),2)*MOD(INT(MOD(INT((F6)/256),256)/2^6),2)*64+MOD(INT(MOD(INT(((4294967295-D6))/256),256)/2^7),2)*MOD(INT(MOD(INT((F6)/256),256)/2^7),2)*128)*256+(MOD(INT(MOD(INT(((4294967295-D6))/65536),256)/2^0),2)*MOD(INT(MOD(INT((F6)/65536),256)/2^0),2)*1+MOD(INT(MOD(INT(((4294967295-D6))/65536),256)/2^1),2)*MOD(INT(MOD(INT((F6)/65536),256)/2^1),2)*2+MOD(INT(MOD(INT(((4294967295-D6))/65536),256)/2^2),2)*MOD(INT(MOD(INT((F6)/65536),256)/2^2),2)*4+MOD(INT(MOD(INT(((4294967295-D6))/65536),256)/2^3),2)*MOD(INT(MOD(INT((F6)/65536),256)/2^3),2)*8+MOD(INT(MOD(INT(((4294967295-D6))/65536),256)/2^4),2)*MOD(INT(MOD(INT((F6)/65536),256)/2^4),2)*16+MOD(INT(MOD(INT(((4294967295-D6))/65536),256)/2^5),2)*MOD(INT(MOD(INT((F6)/65536),256)/2^5),2)*32+MOD(INT(MOD(INT(((4294967295-D6))/65536),256)/2^6),2)*MOD(INT(MOD(INT((F6)/65536),256)/2^6),2)*64+MOD(INT(MOD(INT(((4294967295-D6))/65536),256)/2^7),2)*MOD(INT(MOD(INT((F6)/65536),256)/2^7),2)*128)*65536+(MOD(INT(MOD(INT(((4294967295-D6))/16777216),256)/2^0),2)*MOD(INT(MOD(INT((F6)/16777216),256)/2^0),2)*1+MOD(INT(MOD(INT(((4294967295-D6))/16777216),256)/2^1),2)*MOD(INT(MOD(INT((F6)/16777216),256)/2^1),2)*2+MOD(INT(MOD(INT(((4294967295-D6))/16777216),256)/2^2),2)*MOD(INT(MOD(INT((F6)/16777216),256)/2^2),2)*4+MOD(INT(MOD(INT(((4294967295-D6))/16777216),256)/2^3),2)*MOD(INT(MOD(INT((F6)/16777216),256)/2^3),2)*8+MOD(INT(MOD(INT(((4294967295-D6))/16777216),256)/2^4),2)*MOD(INT(MOD(INT((F6)/16777216),256)/2^4),2)*16+MOD(INT(MOD(INT(((4294967295-D6))/16777216),256)/2^5),2)*MOD(INT(MOD(INT((F6)/16777216),256)/2^5),2)*32+MOD(INT(MOD(INT(((4294967295-D6))/16777216),256)/2^6),2)*MOD(INT(MOD(INT((F6)/16777216),256)/2^6),2)*64+MOD(INT(MOD(INT(((4294967295-D6))/16777216),256)/2^7),2)*MOD(INT(MOD(INT((F6)/16777216),256)/2^7),2)*128)*16777216) -> 2562383102 | K7: =0 -> 0 | L7: =MOD(I7+J7,4294967296) -> 4227596030 | P7: =MOD(MOD(D6,2^2)*2^30+INT(D6/2^2),4294967296) -> 1506887872
B8: 3 | C8: =MOD(H8+L8+G7+1518500249+BF202,4294967296) -> 2640109394 | D8: =C7 -> 3648090350 | E8: =P8 -> 3255206215 | F8: =E7 -> 1506887872 | G8: =F7 -> 2079550178 | H8: =MOD(MOD(C7,2^27)*2^5+INT(C7/2^27),4294967296) -> 774774235 | I8: =((MOD(INT(MOD(INT((D7)/1),256)/2^0),2)*MOD(INT(MOD(INT((E7)/1),256)/2^0),2)*1+MOD(INT(MOD(INT((D7)/1),256)/2^1),2)*MOD(INT(MOD(INT((E7)/1),256)/2^1),2)*2+MOD(INT(MOD(INT((D7)/1),256)/2^2),2)*MOD(INT(MOD(INT((E7)/1),256)/2^2),2)*4+MOD(INT(MOD(INT((D7)/1),256)/2^3),2)*MOD(INT(MOD(INT((E7)/1),256)/2^3),2)*8+MOD(INT(MOD(INT((D7)/1),256)/2^4),2)*MOD(INT(MOD(INT((E7)/1),256)/2^4),2)*16+MOD(INT(MOD(INT((D7)/1),256)/2^5),2)*MOD(INT(MOD(INT((E7)/1),256)/2^5),2)*32+MOD(INT(MOD(INT((D7)/1),256)/2^6),2)*MOD(INT(MOD(INT((E7)/1),256)/2^6),2)*64+MOD(INT(MOD(INT((D7)/1),256)/2^7),2)*MOD(INT(MOD(INT((E7)/1),256)/2^7),2)*128)*1+(MOD(INT(MOD(INT((D7)/256),256)/2^0),2)*MOD(INT(MOD(INT((E7)/256),256)/2^0),2)*1+MOD(INT(MOD(INT((D7)/256),256)/2^1),2)*MOD(INT(MOD(INT((E7)/256),256)/2^1),2)*2+MOD(INT(MOD(INT((D7)/256),256)/2^2),2)*MOD(INT(MOD(INT((E7)/256),256)/2^2),2)*4+MOD(INT(MOD(INT((D7)/256),256)/2^3),2)*MOD(INT(MOD(INT((E7)/256),256)/2^3),2)*8+MOD(INT(MOD(INT((D7)/256),256)/2^4),2)*MOD(INT(MOD(INT((E7)/256),256)/2^4),2)*16+MOD(INT(MOD(INT((D7)/256),256)/2^5),2)*MOD(INT(MOD(INT((E7)/256),256)/2^5),2)*32+MOD(INT(MOD(INT((D7)/256),256)/2^6),2)*MOD(INT(MOD(INT((E7)/256),256)/2^6),2)*64+MOD(INT(MOD(INT((D7)/256),256)/2^7),2)*MOD(INT(MOD(INT((E7)/256),256)/2^7),2)*128)*256+(MOD(INT(MOD(INT((D7)/65536),256)/2^0),2)*MOD(INT(MOD(INT((E7)/65536),256)/2^0),2)*1+MOD(INT(MOD(INT((D7)/65536),256)/2^1),2)*MOD(INT(MOD(INT((E7)/65536),256)/2^1),2)*2+MOD(INT(MOD(INT((D7)/65536),256)/2^2),2)*MOD(INT(MOD(INT((E7)/65536),256)/2^2),2)*4+MOD(INT(MOD(INT((D7)/65536),256)/2^3),2)*MOD(INT(MOD(INT((E7)/65536),256)/2^3),2)*8+MOD(INT(MOD(INT((D7)/65536),256)/2^4),2)*MOD(INT(MOD(INT((E7)/65536),256)/2^4),2)*16+MOD(INT(MOD(INT((D7)/65536),256)/2^5),2)*MOD(INT(MOD(INT((E7)/65536),256)/2^5),2)*32+MOD(INT(MOD(INT((D7)/65536),256)/2^6),2)*MOD(INT(MOD(INT((E7)/65536),256)/2^6),2)*64+MOD(INT(MOD(INT((D7)/65536),256)/2^7),2)*MOD(INT(MOD(INT((E7)/65536),256)/2^7),2)*128)*65536+(MOD(INT(MOD(INT((D7)/16777216),256)/2^0),2)*MOD(INT(MOD(INT((E7)/16777216),256)/2^0),2)*1+MOD(INT(MOD(INT((D7)/16777216),256)/2^1),2)*MOD(INT(MOD(INT((E7)/16777216),256)/2^1),2)*2+MOD(INT(MOD(INT((D7)/16777216),256)/2^2),2)*MOD(INT(MOD(INT((E7)/16777216),256)/2^2),2)*4+MOD(INT(MOD(INT((D7)/16777216),256)/2^3),2)*MOD(INT(MOD(INT((E7)/16777216),256)/2^3),2)*8+MOD(INT(MOD(INT((D7)/16777216),256)/2^4),2)*MOD(INT(MOD(INT((E7)/16777216),256)/2^4),2)*16+MOD(INT(MOD(INT((D7)/16777216),256)/2^5),2)*MOD(INT(MOD(INT((E7)/16777216),256)/2^5),2)*32+MOD(INT(MOD(INT((D7)/16777216),256)/2^6),2)*MOD(INT(MOD(INT((E7)/16777216),256)/2^6),2)*64+MOD(INT(MOD(INT((D7)/16777216),256)/2^7),2)*MOD(INT(MOD(INT((E7)/16777216),256)/2^7),2)*128)*16777216) -> 135266304 | J8: =((MOD(INT(MOD(INT(((4294967295-D7))/1),256)/2^0),2)*MOD(INT(MOD(INT((F7)/1),256)/2^0),2)*1+MOD(INT(MOD(INT(((4294967295-D7))/1),256)/2^1),2)*MOD(INT(MOD(INT((F7)/1),256)/2^1),2)*2+MOD(INT(MOD(INT(((4294967295-D7))/1),256)/2^2),2)*MOD(INT(MOD(INT((F7)/1),256)/2^2),2)*4+MOD(INT(MOD(INT(((4294967295-D7))/1),256)/2^3),2)*MOD(INT(MOD(INT((F7)/1),256)/2^3),2)*8+MOD(INT(MOD(INT(((4294967295-D7))/1),256)/2^4),2)*MOD(INT(MOD(INT((F7)/1),256)/2^4),2)*16+MOD(INT(MOD(INT(((4294967295-D7))/1),256)/2^5),2)*MOD(INT(MOD(INT((F7)/1),256)/2^5),2)*32+MOD(INT(MOD(INT(((4294967295-D7))/1),256)/2^6),2)*MOD(INT(MOD(INT((F7)/1),256)/2^6),2)*64+MOD(INT(MOD(INT(((4294967295-D7))/1),256)/2^7),2)*MOD(INT(MOD(INT((F7)/1),256)/2^7),2)*128)*1+(MOD(INT(MOD(INT(((4294967295-D7))/256),256)/2^0),2)*MOD(INT(MOD(INT((F7)/256),256)/2^0),2)*1+MOD(INT(MOD(INT(((4294967295-D7))/256),256)/2^1),2)*MOD(INT(MOD(INT((F7)/256),256)/2^1),2)*2+MOD(INT(MOD(INT(((4294967295-D7))/256),256)/2^2),2)*MOD(INT(MOD(INT((F7)/256),256)/2^2),2)*4+MOD(INT(MOD(INT(((4294967295-D7))/256),256)/2^3),2)*MOD(INT(MOD(INT((F7)/256),256)/2^3),2)*8+MOD(INT(MOD(INT(((4294967295-D7))/256),256)/2^4),2)*MOD(INT(MOD(INT((F7)/256),256)/2^4),2)*16+MOD(INT(MOD(INT(((4294967295-D7))/256),256)/2^5),2)*MOD(INT(MOD(INT((F7)/256),256)/2^5),2)*32+MOD(INT(MOD(INT(((4294967295-D7))/256),256)/2^6),2)*MOD(INT(MOD(INT((F7)/256),256)/2^6),2)*64+MOD(INT(MOD(INT(((4294967295-D7))/256),256)/2^7),2)*MOD(INT(MOD(INT((F7)/256),256)/2^7),2)*128)*256+(MOD(INT(MOD(INT(((4294967295-D7))/65536),256)/2^0),2)*MOD(INT(MOD(INT((F7)/65536),256)/2^0),2)*1+MOD(INT(MOD(INT(((4294967295-D7))/65536),256)/2^1),2)*MOD(INT(MOD(INT((F7)/65536),256)/2^1),2)*2+MOD(INT(MOD(INT(((4294967295-D7))/65536),256)/2^2),2)*MOD(INT(MOD(INT((F7)/65536),256)/2^2),2)*4+MOD(INT(MOD(INT(((4294967295-D7))/65536),256)/2^3),2)*MOD(INT(MOD(INT((F7)/65536),256)/2^3),2)*8+MOD(INT(MOD(INT(((4294967295-D7))/65536),256)/2^4),2)*MOD(INT(MOD(INT((F7)/65536),256)/2^4),2)*16+MOD(INT(MOD(INT(((4294967295-D7))/65536),256)/2^5),2)*MOD(INT(MOD(INT((F7)/65536),256)/2^5),2)*32+MOD(INT(MOD(INT(((4294967295-D7))/65536),256)/2^6),2)*MOD(INT(MOD(INT((F7)/65536),256)/2^6),2)*64+MOD(INT(MOD(INT(((4294967295-D7))/65536),256)/2^7),2)*MOD(INT(MOD(INT((F7)/65536),256)/2^7),2)*128)*65536+(MOD(INT(MOD(INT(((4294967295-D7))/16777216),256)/2^0),2)*MOD(INT(MOD(INT((F7)/16777216),256)/2^0),2)*1+MOD(INT(MOD(INT(((4294967295-D7))/16777216),256)/2^1),2)*MOD(INT(MOD(INT((F7)/16777216),256)/2^1),2)*2+MOD(INT(MOD(INT(((4294967295-D7))/16777216),256)/2^2),2)*MOD(INT(MOD(INT((F7)/16777216),256)/2^2),2)*4+MOD(INT(MOD(INT(((4294967295-D7))/16777216),256)/2^3),2)*MOD(INT(MOD(INT((F7)/16777216),256)/2^3),2)*8+MOD(INT(MOD(INT(((4294967295-D7))/16777216),256)/2^4),2)*MOD(INT(MOD(INT((F7)/16777216),256)/2^4),2)*16+MOD(INT(MOD(INT(((4294967295-D7))/16777216),256)/2^5),2)*MOD(INT(MOD(INT((F7)/16777216),256)/2^5),2)*32+MOD(INT(MOD(INT(((4294967295-D7))/16777216),256)/2^6),2)*MOD(INT(MOD(INT((F7)/16777216),256)/2^6),2)*64+MOD(INT(MOD(INT(((4294967295-D7))/16777216),256)/2^7),2)*MOD(INT(MOD(INT((F7)/16777216),256)/2^7),2)*128)*16777216) -> 1944152800 | K8: =0 -> 0 | L8: =MOD(I8+J8,4294967296) -> 2079419104 | P8: =MOD(MOD(D7,2^2)*2^30+INT(D7/2^2),4294967296) -> 3255206215
B9: 4 | C9: =MOD(H9+L9+G8+1518500249+BF203,4294967296) -> 1116854036 | D9: =C8 -> 2640109394 | E9: =P9 -> 3059506235 | F9: =E8 -> 3255206215 | G9: =F8 -> 1506887872 | H9: =MOD(MOD(C8,2^27)*2^5+INT(C8/2^27),4294967296) -> 2879122003 | I9: =((MOD(INT(MOD(INT((D8)/1),256)/2^0),2)*MOD(INT(MOD(INT((E8)/1),256)/2^0),2)*1+MOD(INT(MOD(INT((D8)/1),256)/2^1),2)*MOD(INT(MOD(INT((E8)/1),256)/2^1),2)*2+MOD(INT(MOD(INT((D8)/1),256)/2^2),2)*MOD(INT(MOD(INT((E8)/1),256)/2^2),2)*4+MOD(INT(MOD(INT((D8)/1),256)/2^3),2)*MOD(INT(MOD(INT((E8)/1),256)/2^3),2)*8+MOD(INT(MOD(INT((D8)/1),256)/2^4),2)*MOD(INT(MOD(INT((E8)/1),256)/2^4),2)*16+MOD(INT(MOD(INT((D8)/1),256)/2^5),2)*MOD(INT(MOD(INT((E8)/1),256)/2^5),2)*32+MOD(INT(MOD(INT((D8)/1),256)/2^6),2)*MOD(INT(MOD(INT((E8)/1),256)/2^6),2)*64+MOD(INT(MOD(INT((D8)/1),256)/2^7),2)*MOD(INT(MOD(INT((E8)/1),256)/2^7),2)*128)*1+(MOD(INT(MOD(INT((D8)/256),256)/2^0),2)*MOD(INT(MOD(INT((E8)/256),256)/2^0),2)*1+MOD(INT(MOD(INT((D8)/256),256)/2^1),2)*MOD(INT(MOD(INT((E8)/256),256)/2^1),2)*2+MOD(INT(MOD(INT((D8)/256),256)/2^2),2)*MOD(INT(MOD(INT((E8)/256),256)/2^2),2)*4+MOD(INT(MOD(INT((D8)/256),256)/2^3),2)*MOD(INT(MOD(INT((E8)/256),256)/2^3),2)*8+MOD(INT(MOD(INT((D8)/256),256)/2^4),2)*MOD(INT(MOD(INT((E8)/256),256)/2^4),2)*16+MOD(INT(MOD(INT((D8)/256),256)/2^5),2)*MOD(INT(MOD(INT((E8)/256),256)/2^5),2)*32+MOD(INT(MOD(INT((D8)/256),256)/2^6),2)*MOD(INT(MOD(INT((E8)/256),256)/2^6),2)*64+MOD(INT(MOD(INT((D8)/256),256)/2^7),2)*MOD(INT(MOD(INT((E8)/256),256)/2^7),2)*128)*256+(MOD(INT(MOD(INT((D8)/65536),256)/2^0),2)*MOD(INT(MOD(INT((E8)/65536),256)/2^0),2)*1+MOD(INT(MOD(INT((D8)/65536),256)/2^1),2)*MOD(INT(MOD(INT((E8)/65536),256)/2^1),2)*2+MOD(INT(MOD(INT((D8)/65536),256)/2^2),2)*MOD(INT(MOD(INT((E8)/65536),256)/2^2),2)*4+MOD(INT(MOD(INT((D8)/65536),256)/2^3),2)*MOD(INT(MOD(INT((E8)/65536),256)/2^3),2)*8+MOD(INT(MOD(INT((D8)/65536),256)/2^4),2)*MOD(INT(MOD(INT((E8)/65536),256)/2^4),2)*16+MOD(INT(MOD(INT((D8)/65536),256)/2^5),2)*MOD(INT(MOD(INT((E8)/65536),256)/2^5),2)*32+MOD(INT(MOD(INT((D8)/65536),256)/2^6),2)*MOD(INT(MOD(INT((E8)/65536),256)/2^6),2)*64+MOD(INT(MOD(INT((D8)/65536),256)/2^7),2)*MOD(INT(MOD(INT((E8)/65536),256)/2^7),2)*128)*65536+(MOD(INT(MOD(INT((D8)/16777216),256)/2^0),2)*MOD(INT(MOD(INT((E8)/16777216),256)/2^0),2)*1+MOD(INT(MOD(INT((D8)/16777216),256)/2^1),2)*MOD(INT(MOD(INT((E8)/16777216),256)/2^1),2)*2+MOD(INT(MOD(INT((D8)/16777216),256)/2^2),2)*MOD(INT(MOD(INT((E8)/16777216),256)/2^2),2)*4+MOD(INT(MOD(INT((D8)/16777216),256)/2^3),2)*MOD(INT(MOD(INT((E8)/16777216),256)/2^3),2)*8+MOD(INT(MOD(INT((D8)/16777216),256)/2^4),2)*MOD(INT(MOD(INT((E8)/16777216),256)/2^4),2)*16+MOD(INT(MOD(INT((D8)/16777216),256)/2^5),2)*MOD(INT(MOD(INT((E8)/16777216),256)/2^5),2)*32+MOD(INT(MOD(INT((D8)/16777216),256)/2^6),2)*MOD(INT(MOD(INT((E8)/16777216),256)/2^6),2)*64+MOD(INT(MOD(INT((D8)/16777216),256)/2^7),2)*MOD(INT(MOD(INT((E8)/16777216),256)/2^7),2)*128)*16777216) -> 3221225542 | J9: =((MOD(INT(MOD(INT(((4294967295-D8))/1),256)/2^0),2)*MOD(INT(MOD(INT((F8)/1),256)/2^0),2)*1+MOD(INT(MOD(INT(((4294967295-D8))/1),256)/2^1),2)*MOD(INT(MOD(INT((F8)/1),256)/2^1),2)*2+MOD(INT(MOD(INT(((4294967295-D8))/1),256)/2^2),2)*MOD(INT(MOD(INT((F8)/1),256)/2^2),2)*4+MOD(INT(MOD(INT(((4294967295-D8))/1),256)/2^3),2)*MOD(INT(MOD(INT((F8)/1),256)/2^3),2)*8+MOD(INT(MOD(INT(((4294967295-D8))/1),256)/2^4),2)*MOD(INT(MOD(INT((F8)/1),256)/2^4),2)*16+MOD(INT(MOD(INT(((4294967295-D8))/1),256)/2^5),2)*MOD(INT(MOD(INT((F8)/1),256)/2^5),2)*32+MOD(INT(MOD(INT(((4294967295-D8))/1),256)/2^6),2)*MOD(INT(MOD(INT((F8)/1),256)/2^6),2)*64+MOD(INT(MOD(INT(((4294967295-D8))/1),256)/2^7),2)*MOD(INT(MOD(INT((F8)/1),256)/2^7),2)*128)*1+(MOD(INT(MOD(INT(((4294967295-D8))/256),256)/2^0),2)*MOD(INT(MOD(INT((F8)/256),256)/2^0),2)*1+MOD(INT(MOD(INT(((4294967295-D8))/256),256)/2^1),2)*MOD(INT(MOD(INT((F8)/256),256)/2^1),2)*2+MOD(INT(MOD(INT(((4294967295-D8))/256),256)/2^2),2)*MOD(INT(MOD(INT((F8)/256),256)/2^2),2)*4+MOD(INT(MOD(INT(((4294967295-D8))/256),256)/2^3),2)*MOD(INT(MOD(INT((F8)/256),256)/2^3),2)*8+MOD(INT(MOD(INT(((4294967295-D8))/256),256)/2^4),2)*MOD(INT(MOD(INT((F8)/256),256)/2^4),2)*16+MOD(INT(MOD(INT(((4294967295-D8))/256),256)/2^5),2)*MOD(INT(MOD(INT((F8)/256),256)/2^5),2)*32+MOD(INT(MOD(INT(((4294967295-D8))/256),256)/2^6),2)*MOD(INT(MOD(INT((F8)/256),256)/2^6),2)*64+MOD(INT(MOD(INT(((4294967295-D8))/256),256)/2^7),2)*MOD(INT(MOD(INT((F8)/256),256)/2^7),2)*128)*256+(MOD(INT(MOD(INT(((4294967295-D8))/65536),256)/2^0),2)*MOD(INT(MOD(INT((F8)/65536),256)/2^0),2)*1+MOD(INT(MOD(INT(((4294967295-D8))/65536),256)/2^1),2)*MOD(INT(MOD(INT((F8)/65536),256)/2^1),2)*2+MOD(INT(MOD(INT(((4294967295-D8))/65536),256)/2^2),2)*MOD(INT(MOD(INT((F8)/65536),256)/2^2),2)*4+MOD(INT(MOD(INT(((4294967295-D8))/65536),256)/2^3),2)*MOD(INT(MOD(INT((F8)/65536),256)/2^3),2)*8+MOD(INT(MOD(INT(((4294967295-D8))/65536),256)/2^4),2)*MOD(INT(MOD(INT((F8)/65536),256)/2^4),2)*16+MOD(INT(MOD(INT(((4294967295-D8))/65536),256)/2^5),2)*MOD(INT(MOD(INT((F8)/65536),256)/2^5),2)*32+MOD(INT(MOD(INT(((4294967295-D8))/65536),256)/2^6),2)*MOD(INT(MOD(INT((F8)/65536),256)/2^6),2)*64+MOD(INT(MOD(INT(((4294967295-D8))/65536),256)/2^7),2)*MOD(INT(MOD(INT((F8)/65536),256)/2^7),2)*128)*65536+(MOD(INT(MOD(INT(((4294967295-D8))/16777216),256)/2^0),2)*MOD(INT(MOD(INT((F8)/16777216),256)/2^0),2)*1+MOD(INT(MOD(INT(((4294967295-D8))/16777216),256)/2^1),2)*MOD(INT(MOD(INT((F8)/16777216),256)/2^1),2)*2+MOD(INT(MOD(INT(((4294967295-D8))/16777216),256)/2^2),2)*MOD(INT(MOD(INT((F8)/16777216),256)/2^2),2)*4+MOD(INT(MOD(INT(((4294967295-D8))/16777216),256)/2^3),2)*MOD(INT(MOD(INT((F8)/16777216),256)/2^3),2)*8+MOD(INT(MOD(INT(((4294967295-D8))/16777216),256)/2^4),2)*MOD(INT(MOD(INT((F8)/16777216),256)/2^4),2)*16+MOD(INT(MOD(INT(((4294967295-D8))/16777216),256)/2^5),2)*MOD(INT(MOD(INT((F8)/16777216),256)/2^5),2)*32+MOD(INT(MOD(INT(((4294967295-D8))/16777216),256)/2^6),2)*MOD(INT(MOD(INT((F8)/16777216),256)/2^6),2)*64+MOD(INT(MOD(INT(((4294967295-D8))/16777216),256)/2^7),2)*MOD(INT(MOD(INT((F8)/16777216),256)/2^7),2)*128)*16777216) -> 8390656 | K9: =0 -> 0 | L9: =MOD(I9+J9,4294967296) -> 3229616198 | P9: =MOD(MOD(D8,2^2)*2^30+INT(D8/2^2),4294967296) -> 3059506235
B10: 5 | C10: =MOD(H10+L10+G9+1518500249+BF204,4294967296) -> 3706519800 | D10: =C9 -> 1116854036 | E10: =P10 -> 2807510996 | F10: =E9 -> 3059506235 | G10: =F9 -> 3255206215 | H10: =MOD(MOD(C9,2^27)*2^5+INT(C9/2^27),4294967296) -> 1379590792 | I10: =((MOD(INT(MOD(INT((D9)/1),256)/2^0),2)*MOD(INT(MOD(INT((E9)/1),256)/2^0),2)*1+MOD(INT(MOD(INT((D9)/1),256)/2^1),2)*MOD(INT(MOD(INT((E9)/1),256)/2^1),2)*2+MOD(INT(MOD(INT((D9)/1),256)/2^2),2)*MOD(INT(MOD(INT((E9)/1),256)/2^2),2)*4+MOD(INT(MOD(INT((D9)/1),256)/2^3),2)*MOD(INT(MOD(INT((E9)/1),256)/2^3),2)*8+MOD(INT(MOD(INT((D9)/1),256)/2^4),2)*MOD(INT(MOD(INT((E9)/1),256)/2^4),2)*16+MOD(INT(MOD(INT((D9)/1),256)/2^5),2)*MOD(INT(MOD(INT((E9)/1),256)/2^5),2)*32+MOD(INT(MOD(INT((D9)/1),256)/2^6),2)*MOD(INT(MOD(INT((E9)/1),256)/2^6),2)*64+MOD(INT(MOD(INT((D9)/1),256)/2^7),2)*MOD(INT(MOD(INT((E9)/1),256)/2^7),2)*128)*1+(MOD(INT(MOD(INT((D9)/256),256)/2^0),2)*MOD(INT(MOD(INT((E9)/256),256)/2^0),2)*1+MOD(INT(MOD(INT((D9)/256),256)/2^1),2)*MOD(INT(MOD(INT((E9)/256),256)/2^1),2)*2+MOD(INT(MOD(INT((D9)/256),256)/2^2),2)*MOD(INT(MOD(INT((E9)/256),256)/2^2),2)*4+MOD(INT(MOD(INT((D9)/256),256)/2^3),2)*MOD(INT(MOD(INT((E9)/256),256)/2^3),2)*8+MOD(INT(MOD(INT((D9)/256),256)/2^4),2)*MOD(INT(MOD(INT((E9)/256),256)/2^4),2)*16+MOD(INT(MOD(INT((D9)/256),256)/2^5),2)*MOD(INT(MOD(INT((E9)/256),256)/2^5),2)*32+MOD(INT(MOD(INT((D9)/256),256)/2^6),2)*MOD(INT(MOD(INT((E9)/256),256)/2^6),2)*64+MOD(INT(MOD(INT((D9)/256),256)/2^7),2)*MOD(INT(MOD(INT((E9)/256),256)/2^7),2)*128)*256+(MOD(INT(MOD(INT((D9)/65536),256)/2^0),2)*MOD(INT(MOD(INT((E9)/65536),256)/2^0),2)*1+MOD(INT(MOD(INT((D9)/65536),256)/2^1),2)*MOD(INT(MOD(INT((E9)/65536),256)/2^1),2)*2+MOD(INT(MOD(INT((D9)/65536),256)/2^2),2)*MOD(INT(MOD(INT((E9)/65536),256)/2^2),2)*4+MOD(INT(MOD(INT((D9)/65536),256)/2^3),2)*MOD(INT(MOD(INT((E9)/65536),256)/2^3),2)*8+MOD(INT(MOD(INT((D9)/65536),256)/2^4),2)*MOD(INT(MOD(INT((E9)/65536),256)/2^4),2)*16+MOD(INT(MOD(INT((D9)/65536),256)/2^5),2)*MOD(INT(MOD(INT((E9)/65536),256)/2^5),2)*32+MOD(INT(MOD(INT((D9)/65536),256)/2^6),2)*MOD(INT(MOD(INT((E9)/65536),256)/2^6),2)*64+MOD(INT(MOD(INT((D9)/65536),256)/2^7),2)*MOD(INT(MOD(INT((E9)/65536),256)/2^7),2)*128)*65536+(MOD(INT(MOD(INT((D9)/16777216),256)/2^0),2)*MOD(INT(MOD(INT((E9)/16777216),256)/2^0),2)*1+MOD(INT(MOD(INT((D9)/16777216),256)/2^1),2)*MOD(INT(MOD(INT((E9)/16777216),256)/2^1),2)*2+MOD(INT(MOD(INT((D9)/16777216),256)/2^2),2)*MOD(INT(MOD(INT((E9)/16777216),256)/2^2),2)*4+MOD(INT(MOD(INT((D9)/16777216),256)/2^3),2)*MOD(INT(MOD(INT((E9)/16777216),256)/2^3),2)*8+MOD(INT(MOD(INT((D9)/16777216),256)/2^4),2)*MOD(INT(MOD(INT((E9)/16777216),256)/2^4),2)*16+MOD(INT(MOD(INT((D9)/16777216),256)/2^5),2)*MOD(INT(MOD(INT((E9)/16777216),256)/2^5),2)*32+MOD(INT(MOD(INT((D9)/16777216),256)/2^6),2)*MOD(INT(MOD(INT((E9)/16777216),256)/2^6),2)*64+MOD(INT(MOD(INT((D9)/16777216),256)/2^7),2)*MOD(INT(MOD(INT((E9)/16777216),256)/2^7),2)*128)*16777216) -> 2489080850 | J10: =((MOD(INT(MOD(INT(((4294967295-D9))/1),256)/2^0),2)*MOD(INT(MOD(INT((F9)/1),256)/2^0),2)*1+MOD(INT(MOD(INT(((4294967295-D9))/1),256)/2^1),2)*MOD(INT(MOD(INT((F9)/1),256)/2^1),2)*2+MOD(INT(MOD(INT(((4294967295-D9))/1),256)/2^2),2)*MOD(INT(MOD(INT((F9)/1),256)/2^2),2)*4+MOD(INT(MOD(INT(((4294967295-D9))/1),256)/2^3),2)*MOD(INT(MOD(INT((F9)/1),256)/2^3),2)*8+MOD(INT(MOD(INT(((4294967295-D9))/1),256)/2^4),2)*MOD(INT(MOD(INT((F9)/1),256)/2^4),2)*16+MOD(INT(MOD(INT(((4294967295-D9))/1),256)/2^5),2)*MOD(INT(MOD(INT((F9)/1),256)/2^5),2)*32+MOD(INT(MOD(INT(((4294967295-D9))/1),256)/2^6),2)*MOD(INT(MOD(INT((F9)/1),256)/2^6),2)*64+MOD(INT(MOD(INT(((4294967295-D9))/1),256)/2^7),2)*MOD(INT(MOD(INT((F9)/1),256)/2^7),2)*128)*1+(MOD(INT(MOD(INT(((4294967295-D9))/256),256)/2^0),2)*MOD(INT(MOD(INT((F9)/256),256)/2^0),2)*1+MOD(INT(MOD(INT(((4294967295-D9))/256),256)/2^1),2)*MOD(INT(MOD(INT((F9)/256),256)/2^1),2)*2+MOD(INT(MOD(INT(((4294967295-D9))/256),256)/2^2),2)*MOD(INT(MOD(INT((F9)/256),256)/2^2),2)*4+MOD(INT(MOD(INT(((4294967295-D9))/256),256)/2^3),2)*MOD(INT(MOD(INT((F9)/256),256)/2^3),2)*8+MOD(INT(MOD(INT(((4294967295-D9))/256),256)/2^4),2)*MOD(INT(MOD(INT((F9)/256),256)/2^4),2)*16+MOD(INT(MOD(INT(((4294967295-D9))/256),256)/2^5),2)*MOD(INT(MOD(INT((F9)/256),256)/2^5),2)*32+MOD(INT(MOD(INT(((4294967295-D9))/256),256)/2^6),2)*MOD(INT(MOD(INT((F9)/256),256)/2^6),2)*64+MOD(INT(MOD(INT(((4294967295-D9))/256),256)/2^7),2)*MOD(INT(MOD(INT((F9)/256),256)/2^7),2)*128)*256+(MOD(INT(MOD(INT(((4294967295-D9))/65536),256)/2^0),2)*MOD(INT(MOD(INT((F9)/65536),256)/2^0),2)*1+MOD(INT(MOD(INT(((4294967295-D9))/65536),256)/2^1),2)*MOD(INT(MOD(INT((F9)/65536),256)/2^1),2)*2+MOD(INT(MOD(INT(((4294967295-D9))/65536),256)/2^2),2)*MOD(INT(MOD(INT((F9)/65536),256)/2^2),2)*4+MOD(INT(MOD(INT(((4294967295-D9))/65536),256)/2^3),2)*MOD(INT(MOD(INT((F9)/65536),256)/2^3),2)*8+MOD(INT(MOD(INT(((4294967295-D9))/65536),256)/2^4),2)*MOD(INT(MOD(INT((F9)/65536),256)/2^4),2)*16+MOD(INT(MOD(INT(((4294967295-D9))/65536),256)/2^5),2)*MOD(INT(MOD(INT((F9)/65536),256)/2^5),2)*32+MOD(INT(MOD(INT(((4294967295-D9))/65536),256)/2^6),2)*MOD(INT(MOD(INT((F9)/65536),256)/2^6),2)*64+MOD(INT(MOD(INT(((4294967295-D9))/65536),256)/2^7),2)*MOD(INT(MOD(INT((F9)/65536),256)/2^7),2)*128)*65536+(MOD(INT(MOD(INT(((4294967295-D9))/16777216),256)/2^0),2)*MOD(INT(MOD(INT((F9)/16777216),256)/2^0),2)*1+MOD(INT(MOD(INT(((4294967295-D9))/16777216),256)/2^1),2)*MOD(INT(MOD(INT((F9)/16777216),256)/2^1),2)*2+MOD(INT(MOD(INT(((4294967295-D9))/16777216),256)/2^2),2)*MOD(INT(MOD(INT((F9)/16777216),256)/2^2),2)*4+MOD(INT(MOD(INT(((4294967295-D9))/16777216),256)/2^3),2)*MOD(INT(MOD(INT((F9)/16777216),256)/2^3),2)*8+MOD(INT(MOD(INT(((4294967295-D9))/16777216),256)/2^4),2)*MOD(INT(MOD(INT((F9)/16777216),256)/2^4),2)*16+MOD(INT(MOD(INT(((4294967295-D9))/16777216),256)/2^5),2)*MOD(INT(MOD(INT((F9)/16777216),256)/2^5),2)*32+MOD(INT(MOD(INT(((4294967295-D9))/16777216),256)/2^6),2)*MOD(INT(MOD(INT((F9)/16777216),256)/2^6),2)*64+MOD(INT(MOD(INT(((4294967295-D9))/16777216),256)/2^7),2)*MOD(INT(MOD(INT((F9)/16777216),256)/2^7),2)*128)*16777216) -> 1107427333 | K10: =0 -> 0 | L10: =MOD(I10+J10,4294967296) -> 3596508183 | P10: =MOD(MOD(D9,2^2)*2^30+INT(D9/2^2),4294967296) -> 2807510996
B11: 6 | C11: =MOD(H11+L11+G10+1518500249+BF205,4294967296) -> 1887844666 | D11: =C10 -> 3706519800 | E11: =P11 -> 279213509 | F11: =E10 -> 2807510996 | G11: =F10 -> 3059506235 | H11: =MOD(MOD(C10,2^27)*2^5+INT(C10/2^27),4294967296) -> 2644516635 | I11: =((MOD(INT(MOD(INT((D10)/1),256)/2^0),2)*MOD(INT(MOD(INT((E10)/1),256)/2^0),2)*1+MOD(INT(MOD(INT((D10)/1),256)/2^1),2)*MOD(INT(MOD(INT((E10)/1),256)/2^1),2)*2+MOD(INT(MOD(INT((D10)/1),256)/2^2),2)*MOD(INT(MOD(INT((E10)/1),256)/2^2),2)*4+MOD(INT(MOD(INT((D10)/1),256)/2^3),2)*MOD(INT(MOD(INT((E10)/1),256)/2^3),2)*8+MOD(INT(MOD(INT((D10)/1),256)/2^4),2)*MOD(INT(MOD(INT((E10)/1),256)/2^4),2)*16+MOD(INT(MOD(INT((D10)/1),256)/2^5),2)*MOD(INT(MOD(INT((E10)/1),256)/2^5),2)*32+MOD(INT(MOD(INT((D10)/1),256)/2^6),2)*MOD(INT(MOD(INT((E10)/1),256)/2^6),2)*64+MOD(INT(MOD(INT((D10)/1),256)/2^7),2)*MOD(INT(MOD(INT((E10)/1),256)/2^7),2)*128)*1+(MOD(INT(MOD(INT((D10)/256),256)/2^0),2)*MOD(INT(MOD(INT((E10)/256),256)/2^0),2)*1+MOD(INT(MOD(INT((D10)/256),256)/2^1),2)*MOD(INT(MOD(INT((E10)/256),256)/2^1),2)*2+MOD(INT(MOD(INT((D10)/256),256)/2^2),2)*MOD(INT(MOD(INT((E10)/256),256)/2^2),2)*4+MOD(INT(MOD(INT((D10)/256),256)/2^3),2)*MOD(INT(MOD(INT((E10)/256),256)/2^3),2)*8+MOD(INT(MOD(INT((D10)/256),256)/2^4),2)*MOD(INT(MOD(INT((E10)/256),256)/2^4),2)*16+MOD(INT(MOD(INT((D10)/256),256)/2^5),2)*MOD(INT(MOD(INT((E10)/256),256)/2^5),2)*32+MOD(INT(MOD(INT((D10)/256),256)/2^6),2)*MOD(INT(MOD(INT((E10)/256),256)/2^6),2)*64+MOD(INT(MOD(INT((D10)/256),256)/2^7),2)*MOD(INT(MOD(INT((E10)/256),256)/2^7),2)*128)*256+(MOD(INT(MOD(INT((D10)/65536),256)/2^0),2)*MOD(INT(MOD(INT((E10)/65536),256)/2^0),2)*1+MOD(INT(MOD(INT((D10)/65536),256)/2^1),2)*MOD(INT(MOD(INT((E10)/65536),256)/2^1),2)*2+MOD(INT(MOD(INT((D10)/65536),256)/2^2),2)*MOD(INT(MOD(INT((E10)/65536),256)/2^2),2)*4+MOD(INT(MOD(INT((D10)/65536),256)/2^3),2)*MOD(INT(MOD(INT((E10)/65536),256)/2^3),2)*8+MOD(INT(MOD(INT((D10)/65536),256)/2^4),2)*MOD(INT(MOD(INT((E10)/65536),256)/2^4),2)*16+MOD(INT(MOD(INT((D10)/65536),256)/2^5),2)*MOD(INT(MOD(INT((E10)/65536),256)/2^5),2)*32+MOD(INT(MOD(INT((D10)/65536),256)/2^6),2)*MOD(INT(MOD(INT((E10)/65536),256)/2^6),2)*64+MOD(INT(MOD(INT((D10)/65536),256)/2^7),2)*MOD(INT(MOD(INT((E10)/65536),256)/2^7),2)*128)*65536+(MOD(INT(MOD(INT((D10)/16777216),256)/2^0),2)*MOD(INT(MOD(INT((E10)/16777216),256)/2^0),2)*1+MOD(INT(MOD(INT((D10)/16777216),256)/2^1),2)*MOD(INT(MOD(INT((E10)/16777216),256)/2^1),2)*2+MOD(INT(MOD(INT((D10)/16777216),256)/2^2),2)*MOD(INT(MOD(INT((E10)/16777216),256)/2^2),2)*4+MOD(INT(MOD(INT((D10)/16777216),256)/2^3),2)*MOD(INT(MOD(INT((E10)/16777216),256)/2^3),2)*8+MOD(INT(MOD(INT((D10)/16777216),256)/2^4),2)*MOD(INT(MOD(INT((E10)/16777216),256)/2^4),2)*16+MOD(INT(MOD(INT((D10)/16777216),256)/2^5),2)*MOD(INT(MOD(INT((E10)/16777216),256)/2^5),2)*32+MOD(INT(MOD(INT((D10)/16777216),256)/2^6),2)*MOD(INT(MOD(INT((E10)/16777216),256)/2^6),2)*64+MOD(INT(MOD(INT((D10)/16777216),256)/2^7),2)*MOD(INT(MOD(INT((E10)/16777216),256)/2^7),2)*128)*16777216) -> 34674452 | J11: =((MOD(INT(MOD(INT(((4294967295-D10))/1),256)/2^0),2)*MOD(INT(MOD(INT((F10)/1),256)/2^0),2)*1+MOD(INT(MOD(INT(((4294967295-D10))/1),256)/2^1),2)*MOD(INT(MOD(INT((F10)/1),256)/2^1),2)*2+MOD(INT(MOD(INT(((4294967295-D10))/1),256)/2^2),2)*MOD(INT(MOD(INT((F10)/1),256)/2^2),2)*4+MOD(INT(MOD(INT(((4294967295-D10))/1),256)/2^3),2)*MOD(INT(MOD(INT((F10)/1),256)/2^3),2)*8+MOD(INT(MOD(INT(((4294967295-D10))/1),256)/2^4),2)*MOD(INT(MOD(INT((F10)/1),256)/2^4),2)*16+MOD(INT(MOD(INT(((4294967295-D10))/1),256)/2^5),2)*MOD(INT(MOD(INT((F10)/1),256)/2^5),2)*32+MOD(INT(MOD(INT(((4294967295-D10))/1),256)/2^6),2)*MOD(INT(MOD(INT((F10)/1),256)/2^6),2)*64+MOD(INT(MOD(INT(((4294967295-D10))/1),256)/2^7),2)*MOD(INT(MOD(INT((F10)/1),256)/2^7),2)*128)*1+(MOD(INT(MOD(INT(((4294967295-D10))/256),256)/2^0),2)*MOD(INT(MOD(INT((F10)/256),256)/2^0),2)*1+MOD(INT(MOD(INT(((4294967295-D10))/256),256)/2^1),2)*MOD(INT(MOD(INT((F10)/256),256)/2^1),2)*2+MOD(INT(MOD(INT(((4294967295-D10))/256),256)/2^2),2)*MOD(INT(MOD(INT((F10)/256),256)/2^2),2)*4+MOD(INT(MOD(INT(((4294967295-D10))/256),256)/2^3),2)*MOD(INT(MOD(INT((F10)/256),256)/2^3),2)*8+MOD(INT(MOD(INT(((4294967295-D10))/256),256)/2^4),2)*MOD(INT(MOD(INT((F10)/256),256)/2^4),2)*16+MOD(INT(MOD(INT(((4294967295-D10))/256),256)/2^5),2)*MOD(INT(MOD(INT((F10)/256),256)/2^5),2)*32+MOD(INT(MOD(INT(((4294967295-D10))/256),256)/2^6),2)*MOD(INT(MOD(INT((F10)/256),256)/2^6),2)*64+MOD(INT(MOD(INT(((4294967295-D10))/256),256)/2^7),2)*MOD(INT(MOD(INT((F10)/256),256)/2^7),2)*128)*256+(MOD(INT(MOD(INT(((4294967295-D10))/65536),256)/2^0),2)*MOD(INT(MOD(INT((F10)/65536),256)/2^0),2)*1+MOD(INT(MOD(INT(((4294967295-D10))/65536),256)/2^1),2)*MOD(INT(MOD(INT((F10)/65536),256)/2^1),2)*2+MOD(INT(MOD(INT(((4294967295-D10))/65536),256)/2^2),2)*MOD(INT(MOD(INT((F10)/65536),256)/2^2),2)*4+MOD(INT(MOD(INT(((4294967295-D10))/65536),256)/2^3),2)*MOD(INT(MOD(INT((F10)/65536),256)/2^3),2)*8+MOD(INT(MOD(INT(((4294967295-D10))/65536),256)/2^4),2)*MOD(INT(MOD(INT((F10)/65536),256)/2^4),2)*16+MOD(INT(MOD(INT(((4294967295-D10))/65536),256)/2^5),2)*MOD(INT(MOD(INT((F10)/65536),256)/2^5),2)*32+MOD(INT(MOD(INT(((4294967295-D10))/65536),256)/2^6),2)*MOD(INT(MOD(INT((F10)/65536),256)/2^6),2)*64+MOD(INT(MOD(INT(((4294967295-D10))/65536),256)/2^7),2)*MOD(INT(MOD(INT((F10)/65536),256)/2^7),2)*128)*65536+(MOD(INT(MOD(INT(((4294967295-D10))/16777216),256)/2^0),2)*MOD(INT(MOD(INT((F10)/16777216),256)/2^0),2)*1+MOD(INT(MOD(INT(((4294967295-D10))/16777216),256)/2^1),2)*MOD(INT(MOD(INT((F10)/16777216),256)/2^1),2)*2+MOD(INT(MOD(INT(((4294967295-D10))/16777216),256)/2^2),2)*MOD(INT(MOD(INT((F10)/16777216),256)/2^2),2)*4+MOD(INT(MOD(INT(((4294967295-D10))/16777216),256)/2^3),2)*MOD(INT(MOD(INT((F10)/16777216),256)/2^3),2)*8+MOD(INT(MOD(INT(((4294967295-D10))/16777216),256)/2^4),2)*MOD(INT(MOD(INT((F10)/16777216),256)/2^4),2)*16+MOD(INT(MOD(INT(((4294967295-D10))/16777216),256)/2^5),2)*MOD(INT(MOD(INT((F10)/16777216),256)/2^5),2)*32+MOD(INT(MOD(INT(((4294967295-D10))/16777216),256)/2^6),2)*MOD(INT(MOD(INT((F10)/16777216),256)/2^6),2)*64+MOD(INT(MOD(INT(((4294967295-D10))/16777216),256)/2^7),2)*MOD(INT(MOD(INT((F10)/16777216),256)/2^7),2)*128)*16777216) -> 3024881707 | K11: =0 -> 0 | L11: =MOD(I11+J11,4294967296) -> 3059556159 | P11: =MOD(MOD(D10,2^2)*2^30+INT(D10/2^2),4294967296) -> 279213509
B12: 7 | C12: =MOD(H12+L12+G11+1518500249+BF206,4294967296) -> 1432106214 | D12: =C11 -> 1887844666 | E12: =P12 -> 926629950 | F12: =E11 -> 279213509 | G12: =F11 -> 2807510996 | H12: =MOD(MOD(C11,2^27)*2^5+INT(C11/2^27),4294967296) -> 281487182 | I12: =((MOD(INT(MOD(INT((D11)/1),256)/2^0),2)*MOD(INT(MOD(INT((E11)/1),256)/2^0),2)*1+MOD(INT(MOD(INT((D11)/1),256)/2^1),2)*MOD(INT(MOD(INT((E11)/1),256)/2^1),2)*2+MOD(INT(MOD(INT((D11)/1),256)/2^2),2)*MOD(INT(MOD(INT((E11)/1),256)/2^2),2)*4+MOD(INT(MOD(INT((D11)/1),256)/2^3),2)*MOD(INT(MOD(INT((E11)/1),256)/2^3),2)*8+MOD(INT(MOD(INT((D11)/1),256)/2^4),2)*MOD(INT(MOD(INT((E11)/1),256)/2^4),2)*16+MOD(INT(MOD(INT((D11)/1),256)/2^5),2)*MOD(INT(MOD(INT((E11)/1),256)/2^5),2)*32+MOD(INT(MOD(INT((D11)/1),256)/2^6),2)*MOD(INT(MOD(INT((E11)/1),256)/2^6),2)*64+MOD(INT(MOD(INT((D11)/1),256)/2^7),2)*MOD(INT(MOD(INT((E11)/1),256)/2^7),2)*128)*1+(MOD(INT(MOD(INT((D11)/256),256)/2^0),2)*MOD(INT(MOD(INT((E11)/256),256)/2^0),2)*1+MOD(INT(MOD(INT((D11)/256),256)/2^1),2)*MOD(INT(MOD(INT((E11)/256),256)/2^1),2)*2+MOD(INT(MOD(INT((D11)/256),256)/2^2),2)*MOD(INT(MOD(INT((E11)/256),256)/2^2),2)*4+MOD(INT(MOD(INT((D11)/256),256)/2^3),2)*MOD(INT(MOD(INT((E11)/256),256)/2^3),2)*8+MOD(INT(MOD(INT((D11)/256),256)/2^4),2)*MOD(INT(MOD(INT((E11)/256),256)/2^4),2)*16+MOD(INT(MOD(INT((D11)/256),256)/2^5),2)*MOD(INT(MOD(INT((E11)/256),256)/2^5),2)*32+MOD(INT(MOD(INT((D11)/256),256)/2^6),2)*MOD(INT(MOD(INT((E11)/256),256)/2^6),2)*64+MOD(INT(MOD(INT((D11)/256),256)/2^7),2)*MOD(INT(MOD(INT((E11)/256),256)/2^7),2)*128)*256+(MOD(INT(MOD(INT((D11)/65536),256)/2^0),2)*MOD(INT(MOD(INT((E11)/65536),256)/2^0),2)*1+MOD(INT(MOD(INT((D11)/65536),256)/2^1),2)*MOD(INT(MOD(INT((E11)/65536),256)/2^1),2)*2+MOD(INT(MOD(INT((D11)/65536),256)/2^2),2)*MOD(INT(MOD(INT((E11)/65536),256)/2^2),2)*4+MOD(INT(MOD(INT((D11)/65536),256)/2^3),2)*MOD(INT(MOD(INT((E11)/65536),256)/2^3),2)*8+MOD(INT(MOD(INT((D11)/65536),256)/2^4),2)*MOD(INT(MOD(INT((E11)/65536),256)/2^4),2)*16+MOD(INT(MOD(INT((D11)/65536),256)/2^5),2)*MOD(INT(MOD(INT((E11)/65536),256)/2^5),2)*32+MOD(INT(MOD(INT((D11)/65536),256)/2^6),2)*MOD(INT(MOD(INT((E11)/65536),256)/2^6),2)*64+MOD(INT(MOD(INT((D11)/65536),256)/2^7),2)*MOD(INT(MOD(INT((E11)/65536),256)/2^7),2)*128)*65536+(MOD(INT(MOD(INT((D11)/16777216),256)/2^0),2)*MOD(INT(MOD(INT((E11)/16777216),256)/2^0),2)*1+MOD(INT(MOD(INT((D11)/16777216),256)/2^1),2)*MOD(INT(MOD(INT((E11)/16777216),256)/2^1),2)*2+MOD(INT(MOD(INT((D11)/16777216),256)/2^2),2)*MOD(INT(MOD(INT((E11)/16777216),256)/2^2),2)*4+MOD(INT(MOD(INT((D11)/16777216),256)/2^3),2)*MOD(INT(MOD(INT((E11)/16777216),256)/2^3),2)*8+MOD(INT(MOD(INT((D11)/16777216),256)/2^4),2)*MOD(INT(MOD(INT((E11)/16777216),256)/2^4),2)*16+MOD(INT(MOD(INT((D11)/16777216),256)/2^5),2)*MOD(INT(MOD(INT((E11)/16777216),256)/2^5),2)*32+MOD(INT(MOD(INT((D11)/16777216),256)/2^6),2)*MOD(INT(MOD(INT((E11)/16777216),256)/2^6),2)*64+MOD(INT(MOD(INT((D11)/16777216),256)/2^7),2)*MOD(INT(MOD(INT((E11)/16777216),256)/2^7),2)*128)*16777216) -> 279183552 | J12: =((MOD(INT(MOD(INT(((4294967295-D11))/1),256)/2^0),2)*MOD(INT(MOD(INT((F11)/1),256)/2^0),2)*1+MOD(INT(MOD(INT(((4294967295-D11))/1),256)/2^1),2)*MOD(INT(MOD(INT((F11)/1),256)/2^1),2)*2+MOD(INT(MOD(INT(((4294967295-D11))/1),256)/2^2),2)*MOD(INT(MOD(INT((F11)/1),256)/2^2),2)*4+MOD(INT(MOD(INT(((4294967295-D11))/1),256)/2^3),2)*MOD(INT(MOD(INT((F11)/1),256)/2^3),2)*8+MOD(INT(MOD(INT(((4294967295-D11))/1),256)/2^4),2)*MOD(INT(MOD(INT((F11)/1),256)/2^4),2)*16+MOD(INT(MOD(INT(((4294967295-D11))/1),256)/2^5),2)*MOD(INT(MOD(INT((F11)/1),256)/2^5),2)*32+MOD(INT(MOD(INT(((4294967295-D11))/1),256)/2^6),2)*MOD(INT(MOD(INT((F11)/1),256)/2^6),2)*64+MOD(INT(MOD(INT(((4294967295-D11))/1),256)/2^7),2)*MOD(INT(MOD(INT((F11)/1),256)/2^7),2)*128)*1+(MOD(INT(MOD(INT(((4294967295-D11))/256),256)/2^0),2)*MOD(INT(MOD(INT((F11)/256),256)/2^0),2)*1+MOD(INT(MOD(INT(((4294967295-D11))/256),256)/2^1),2)*MOD(INT(MOD(INT((F11)/256),256)/2^1),2)*2+MOD(INT(MOD(INT(((4294967295-D11))/256),256)/2^2),2)*MOD(INT(MOD(INT((F11)/256),256)/2^2),2)*4+MOD(INT(MOD(INT(((4294967295-D11))/256),256)/2^3),2)*MOD(INT(MOD(INT((F11)/256),256)/2^3),2)*8+MOD(INT(MOD(INT(((4294967295-D11))/256),256)/2^4),2)*MOD(INT(MOD(INT((F11)/256),256)/2^4),2)*16+MOD(INT(MOD(INT(((4294967295-D11))/256),256)/2^5),2)*MOD(INT(MOD(INT((F11)/256),256)/2^5),2)*32+MOD(INT(MOD(INT(((4294967295-D11))/256),256)/2^6),2)*MOD(INT(MOD(INT((F11)/256),256)/2^6),2)*64+MOD(INT(MOD(INT(((4294967295-D11))/256),256)/2^7),2)*MOD(INT(MOD(INT((F11)/256),256)/2^7),2)*128)*256+(MOD(INT(MOD(INT(((4294967295-D11))/65536),256)/2^0),2)*MOD(INT(MOD(INT((F11)/65536),256)/2^0),2)*1+MOD(INT(MOD(INT(((4294967295-D11))/65536),256)/2^1),2)*MOD(INT(MOD(INT((F11)/65536),256)/2^1),2)*2+MOD(INT(MOD(INT(((4294967295-D11))/65536),256)/2^2),2)*MOD(INT(MOD(INT((F11)/65536),256)/2^2),2)*4+MOD(INT(MOD(INT(((4294967295-D11))/65536),256)/2^3),2)*MOD(INT(MOD(INT((F11)/65536),256)/2^3),2)*8+MOD(INT(MOD(INT(((4294967295-D11))/65536),256)/2^4),2)*MOD(INT(MOD(INT((F11)/65536),256)/2^4),2)*16+MOD(INT(MOD(INT(((4294967295-D11))/65536),256)/2^5),2)*MOD(INT(MOD(INT((F11)/65536),256)/2^5),2)*32+MOD(INT(MOD(INT(((4294967295-D11))/65536),256)/2^6),2)*MOD(INT(MOD(INT((F11)/65536),256)/2^6),2)*64+MOD(INT(MOD(INT(((4294967295-D11))/65536),256)/2^7),2)*MOD(INT(MOD(INT((F11)/65536),256)/2^7),2)*128)*65536+(MOD(INT(MOD(INT(((4294967295-D11))/16777216),256)/2^0),2)*MOD(INT(MOD(INT((F11)/16777216),256)/2^0),2)*1+MOD(INT(MOD(INT(((4294967295-D11))/16777216),256)/2^1),2)*MOD(INT(MOD(INT((F11)/16777216),256)/2^1),2)*2+MOD(INT(MOD(INT(((4294967295-D11))/16777216),256)/2^2),2)*MOD(INT(MOD(INT((F11)/16777216),256)/2^2),2)*4+MOD(INT(MOD(INT(((4294967295-D11))/16777216),256)/2^3),2)*MOD(INT(MOD(INT((F11)/16777216),256)/2^3),2)*8+MOD(INT(MOD(INT(((4294967295-D11))/16777216),256)/2^4),2)*MOD(INT(MOD(INT((F11)/16777216),256)/2^4),2)*16+MOD(INT(MOD(INT(((4294967295-D11))/16777216),256)/2^5),2)*MOD(INT(MOD(INT((F11)/16777216),256)/2^5),2)*32+MOD(INT(MOD(INT(((4294967295-D11))/16777216),256)/2^6),2)*MOD(INT(MOD(INT((F11)/16777216),256)/2^6),2)*64+MOD(INT(MOD(INT(((4294967295-D11))/16777216),256)/2^7),2)*MOD(INT(MOD(INT((F11)/16777216),256)/2^7),2)*128)*16777216) -> 588396292 | K12: =0 -> 0 | L12: =MOD(I12+J12,4294967296) -> 867579844 | P12: =MOD(MOD(D11,2^2)*2^30+INT(D11/2^2),4294967296) -> 926629950
B13: 8 | C13: =MOD(H13+L13+G12+1518500249+BF207,4294967296) -> 3716322102 | D13: =C12 -> 1432106214 | E13: =P13 -> 2619444814 | F13: =E12 -> 926629950 | G13: =F12 -> 279213509 | H13: =MOD(MOD(C12,2^27)*2^5+INT(C12/2^27),4294967296) -> 2877725898 | I13: =((MOD(INT(MOD(INT((D12)/1),256)/2^0),2)*MOD(INT(MOD(INT((E12)/1),256)/2^0),2)*1+MOD(INT(MOD(INT((D12)/1),256)/2^1),2)*MOD(INT(MOD(INT((E12)/1),256)/2^1),2)*2+MOD(INT(MOD(INT((D12)/1),256)/2^2),2)*MOD(INT(MOD(INT((E12)/1),256)/2^2),2)*4+MOD(INT(MOD(INT((D12)/1),256)/2^3),2)*MOD(INT(MOD(INT((E12)/1),256)/2^3),2)*8+MOD(INT(MOD(INT((D12)/1),256)/2^4),2)*MOD(INT(MOD(INT((E12)/1),256)/2^4),2)*16+MOD(INT(MOD(INT((D12)/1),256)/2^5),2)*MOD(INT(MOD(INT((E12)/1),256)/2^5),2)*32+MOD(INT(MOD(INT((D12)/1),256)/2^6),2)*MOD(INT(MOD(INT((E12)/1),256)/2^6),2)*64+MOD(INT(MOD(INT((D12)/1),256)/2^7),2)*MOD(INT(MOD(INT((E12)/1),256)/2^7),2)*128)*1+(MOD(INT(MOD(INT((D12)/256),256)/2^0),2)*MOD(INT(MOD(INT((E12)/256),256)/2^0),2)*1+MOD(INT(MOD(INT((D12)/256),256)/2^1),2)*MOD(INT(MOD(INT((E12)/256),256)/2^1),2)*2+MOD(INT(MOD(INT((D12)/256),256)/2^2),2)*MOD(INT(MOD(INT((E12)/256),256)/2^2),2)*4+MOD(INT(MOD(INT((D12)/256),256)/2^3),2)*MOD(INT(MOD(INT((E12)/256),256)/2^3),2)*8+MOD(INT(MOD(INT((D12)/256),256)/2^4),2)*MOD(INT(MOD(INT((E12)/256),256)/2^4),2)*16+MOD(INT(MOD(INT((D12)/256),256)/2^5),2)*MOD(INT(MOD(INT((E12)/256),256)/2^5),2)*32+MOD(INT(MOD(INT((D12)/256),256)/2^6),2)*MOD(INT(MOD(INT((E12)/256),256)/2^6),2)*64+MOD(INT(MOD(INT((D12)/256),256)/2^7),2)*MOD(INT(MOD(INT((E12)/256),256)/2^7),2)*128)*256+(MOD(INT(MOD(INT((D12)/65536),256)/2^0),2)*MOD(INT(MOD(INT((E12)/65536),256)/2^0),2)*1+MOD(INT(MOD(INT((D12)/65536),256)/2^1),2)*MOD(INT(MOD(INT((E12)/65536),256)/2^1),2)*2+MOD(INT(MOD(INT((D12)/65536),256)/2^2),2)*MOD(INT(MOD(INT((E12)/65536),256)/2^2),2)*4+MOD(INT(MOD(INT((D12)/65536),256)/2^3),2)*MOD(INT(MOD(INT((E12)/65536),256)/2^3),2)*8+MOD(INT(MOD(INT((D12)/65536),256)/2^4),2)*MOD(INT(MOD(INT((E12)/65536),256)/2^4),2)*16+MOD(INT(MOD(INT((D12)/65536),256)/2^5),2)*MOD(INT(MOD(INT((E12)/65536),256)/2^5),2)*32+MOD(INT(MOD(INT((D12)/65536),256)/2^6),2)*MOD(INT(MOD(INT((E12)/65536),256)/2^6),2)*64+MOD(INT(MOD(INT((D12)/65536),256)/2^7),2)*MOD(INT(MOD(INT((E12)/65536),256)/2^7),2)*128)*65536+(MOD(INT(MOD(INT((D12)/16777216),256)/2^0),2)*MOD(INT(MOD(INT((E12)/16777216),256)/2^0),2)*1+MOD(INT(MOD(INT((D12)/16777216),256)/2^1),2)*MOD(INT(MOD(INT((E12)/16777216),256)/2^1),2)*2+MOD(INT(MOD(INT((D12)/16777216),256)/2^2),2)*MOD(INT(MOD(INT((E12)/16777216),256)/2^2),2)*4+MOD(INT(MOD(INT((D12)/16777216),256)/2^3),2)*MOD(INT(MOD(INT((E12)/16777216),256)/2^3),2)*8+MOD(INT(MOD(INT((D12)/16777216),256)/2^4),2)*MOD(INT(MOD(INT((E12)/16777216),256)/2^4),2)*16+MOD(INT(MOD(INT((D12)/16777216),256)/2^5),2)*MOD(INT(MOD(INT((E12)/16777216),256)/2^5),2)*32+MOD(INT(MOD(INT((D12)/16777216),256)/2^6),2)*MOD(INT(MOD(INT((E12)/16777216),256)/2^6),2)*64+MOD(INT(MOD(INT((D12)/16777216),256)/2^7),2)*MOD(INT(MOD(INT((E12)/16777216),256)/2^7),2)*128)*16777216) -> 805437498 | J13: =((MOD(INT(MOD(INT(((4294967295-D12))/1),256)/2^0),2)*MOD(INT(MOD(INT((F12)/1),256)/2^0),2)*1+MOD(INT(MOD(INT(((4294967295-D12))/1),256)/2^1),2)*MOD(INT(MOD(INT((F12)/1),256)/2^1),2)*2+MOD(INT(MOD(INT(((4294967295-D12))/1),256)/2^2),2)*MOD(INT(MOD(INT((F12)/1),256)/2^2),2)*4+MOD(INT(MOD(INT(((4294967295-D12))/1),256)/2^3),2)*MOD(INT(MOD(INT((F12)/1),256)/2^3),2)*8+MOD(INT(MOD(INT(((4294967295-D12))/1),256)/2^4),2)*MOD(INT(MOD(INT((F12)/1),256)/2^4),2)*16+MOD(INT(MOD(INT(((4294967295-D12))/1),256)/2^5),2)*MOD(INT(MOD(INT((F12)/1),256)/2^5),2)*32+MOD(INT(MOD(INT(((4294967295-D12))/1),256)/2^6),2)*MOD(INT(MOD(INT((F12)/1),256)/2^6),2)*64+MOD(INT(MOD(INT(((4294967295-D12))/1),256)/2^7),2)*MOD(INT(MOD(INT((F12)/1),256)/2^7),2)*128)*1+(MOD(INT(MOD(INT(((4294967295-D12))/256),256)/2^0),2)*MOD(INT(MOD(INT((F12)/256),256)/2^0),2)*1+MOD(INT(MOD(INT(((4294967295-D12))/256),256)/2^1),2)*MOD(INT(MOD(INT((F12)/256),256)/2^1),2)*2+MOD(INT(MOD(INT(((4294967295-D12))/256),256)/2^2),2)*MOD(INT(MOD(INT((F12)/256),256)/2^2),2)*4+MOD(INT(MOD(INT(((4294967295-D12))/256),256)/2^3),2)*MOD(INT(MOD(INT((F12)/256),256)/2^3),2)*8+MOD(INT(MOD(INT(((4294967295-D12))/256),256)/2^4),2)*MOD(INT(MOD(INT((F12)/256),256)/2^4),2)*16+MOD(INT(MOD(INT(((4294967295-D12))/256),256)/2^5),2)*MOD(INT(MOD(INT((F12)/256),256)/2^5),2)*32+MOD(INT(MOD(INT(((4294967295-D12))/256),256)/2^6),2)*MOD(INT(MOD(INT((F12)/256),256)/2^6),2)*64+MOD(INT(MOD(INT(((4294967295-D12))/256),256)/2^7),2)*MOD(INT(MOD(INT((F12)/256),256)/2^7),2)*128)*256+(MOD(INT(MOD(INT(((4294967295-D12))/65536),256)/2^0),2)*MOD(INT(MOD(INT((F12)/65536),256)/2^0),2)*1+MOD(INT(MOD(INT(((4294967295-D12))/65536),256)/2^1),2)*MOD(INT(MOD(INT((F12)/65536),256)/2^1),2)*2+MOD(INT(MOD(INT(((4294967295-D12))/65536),256)/2^2),2)*MOD(INT(MOD(INT((F12)/65536),256)/2^2),2)*4+MOD(INT(MOD(INT(((4294967295-D12))/65536),256)/2^3),2)*MOD(INT(MOD(INT((F12)/65536),256)/2^3),2)*8+MOD(INT(MOD(INT(((4294967295-D12))/65536),256)/2^4),2)*MOD(INT(MOD(INT((F12)/65536),256)/2^4),2)*16+MOD(INT(MOD(INT(((4294967295-D12))/65536),256)/2^5),2)*MOD(INT(MOD(INT((F12)/65536),256)/2^5),2)*32+MOD(INT(MOD(INT(((4294967295-D12))/65536),256)/2^6),2)*MOD(INT(MOD(INT((F12)/65536),256)/2^6),2)*64+MOD(INT(MOD(INT(((4294967295-D12))/65536),256)/2^7),2)*MOD(INT(MOD(INT((F12)/65536),256)/2^7),2)*128)*65536+(MOD(INT(MOD(INT(((4294967295-D12))/16777216),256)/2^0),2)*MOD(INT(MOD(INT((F12)/16777216),256)/2^0),2)*1+MOD(INT(MOD(INT(((4294967295-D12))/16777216),256)/2^1),2)*MOD(INT(MOD(INT((F12)/16777216),256)/2^1),2)*2+MOD(INT(MOD(INT(((4294967295-D12))/16777216),256)/2^2),2)*MOD(INT(MOD(INT((F12)/16777216),256)/2^2),2)*4+MOD(INT(MOD(INT(((4294967295-D12))/16777216),256)/2^3),2)*MOD(INT(MOD(INT((F12)/16777216),256)/2^3),2)*8+MOD(INT(MOD(INT(((4294967295-D12))/16777216),256)/2^4),2)*MOD(INT(MOD(INT((F12)/16777216),256)/2^4),2)*16+MOD(INT(MOD(INT(((4294967295-D12))/16777216),256)/2^5),2)*MOD(INT(MOD(INT((F12)/16777216),256)/2^5),2)*32+MOD(INT(MOD(INT(((4294967295-D12))/16777216),256)/2^6),2)*MOD(INT(MOD(INT((F12)/16777216),256)/2^6),2)*64+MOD(INT(MOD(INT(((4294967295-D12))/16777216),256)/2^7),2)*MOD(INT(MOD(INT((F12)/16777216),256)/2^7),2)*128)*16777216) -> 2114757 | K13: =0 -> 0 | L13: =MOD(I13+J13,4294967296) -> 807552255 | P13: =MOD(MOD(D12,2^2)*2^30+INT(D12/2^2),4294967296) -> 2619444814
