Workbook

Sheet 🔐 SHA-256
B1: 🔐 SHA-256 Calculator — pure Excel formulas, no VBA
B2: Requires Excel 2013+ · Pure INT/MOD/MID formulas · No macros
B4: ✏️ ENTER A WORD (1–7 ASCII characters):
B5: hello
B7: 🔑 SHA-256 RESULT:
B8: ='⚙️ Computation'!E2 -> 2cf24dba5fb0a30e26e83b2ac5b9e29e1b161e5c1fa7425e73043362938b9824
B10: 📌 Sheets: 📖 How SHA-256 Works | 🔤 ASCII Encoding | 📦 SHA-256 Constants | ⚙️ Computation
B12: ✅ Verified: "hello" → 2cf24dba5fb0a30e26e83b2ac5b9e29e1b161e5c1fa7425e73043362938b9824
B13: ⚠️ Maximum 7 characters · ASCII only · Requires Excel 2013+

Sheet 📖 How SHA-256 Works
B1: 📖 How SHA-256 Works — step-by-step explanation
B2: Step 1 · Входная строка
B3: Берём любую строку (например «hello»). Каждый символ — это байт (8 бит). «hello» → [104, 101, 108, 108, 111] = 5 байт = 40 бит.
B4: Step 2 · Padding
B5: После последнего байта добавляем 0x80. Затем нули, пока длина ≡ 56 (mod 64). Отличие от MD5: SHA-256 использует BIG-ENDIAN для всех чисел.
B6: Step 3 · Поле длины (big-endian)
B7: В байты 56–63 записываем длину в битах как 64-битное BIG-ENDIAN число. «hello» = 40 бит → байты 56-62 = [0,0,0,0,0,0,0], байт 63 = 40. Итого 512 бит = 16 слов M[0..15] по 32 бита (big-endian).
B8: Step 4 · Начальное состояние
B9: Восемь 32-битных констант (дробные части √ первых 8 простых чисел): H0=0x6a09e667 H1=0xbb67ae85 H2=0x3c6ef372 H3=0xa54ff53a H4=0x510e527f H5=0x9b05688c H6=0x1f83d9ab H7=0x5be0cd19
B10: Step 5 · Message Schedule W[0..63]
B11: Сначала W[0..15] = M[0..15] (слова из входного блока). Затем для i=16..63: s0 = ROTR(W[i-15],7) ⊕ ROTR(W[i-15],18) ⊕ SHR(W[i-15],3) s1 = ROTR(W[i-2],17) ⊕ ROTR(W[i-2],19) ⊕ SHR(W[i-2],10) W[i] = ADD32(W[i-16], s0, W[i-7], s1) Эти 64 слова перемешивают входные данные перед сжатием.
B12: Step 6 · 64 раунда сжатия
... B21: Побитовые операции через INT/MOD: · AND32(a,b): разбивка на 4 байта × 8 бит · XOR32(a,b) = a + b − 2·AND32(a,b) · XOR3(x,y,z) = XOR(XOR(x,y), z) — нужно 2 вызова AND32 + 2 пром. ячейки · ROTR32(x,n) = MOD(MOD(x,2^n)·2^(32−n) + INT(x/2^n), 2³²) · SHR32(x,n) = INT(x/2^n) · Ch и Maj используют те же AND32 с промежуточными ячейками-помощниками

Sheet 🔤 ASCII Encoding
B1: 🔤 Input string → ASCII → binary bits
B2: № | C2: Char | D2: ASCII | E2: Hex | F2: б7 | G2: б6 | H2: б5 | I2: б4 | J2: б3 | K2: б2 | L2: б1 | M2: б0
B3: 1 | C3: =IF(LEN('🔐 SHA-256'!B5)>=1,MID('🔐 SHA-256'!B5,1,1),"-") -> h | D3: =IF(C3<>"-",CODE(C3),"") -> 104 | E3: =IF(D3<>"",MID("0123456789abcdef",MOD(INT(D3/16),16)+1,1)&MID("0123456789abcdef",MOD(MOD(D3,16),16)+1,1),"") -> 68 | F3: =IF(D3<>"",MOD(INT(D3/2^7),2),"") -> 0 | G3: =IF(D3<>"",MOD(INT(D3/2^6),2),"") -> 1 | H3: =IF(D3<>"",MOD(INT(D3/2^5),2),"") -> 1 | I3: =IF(D3<>"",MOD(INT(D3/2^4),2),"") -> 0 | J3: =IF(D3<>"",MOD(INT(D3/2^3),2),"") -> 1 | K3: =IF(D3<>"",MOD(INT(D3/2^2),2),"") -> 0 | L3: =IF(D3<>"",MOD(INT(D3/2^1),2),"") -> 0 | M3: =IF(D3<>"",MOD(INT(D3/2^0),2),"") -> 0
B4: 2 | C4: =IF(LEN('🔐 SHA-256'!B5)>=2,MID('🔐 SHA-256'!B5,2,1),"-") -> e | D4: =IF(C4<>"-",CODE(C4),"") -> 101 | E4: =IF(D4<>"",MID("0123456789abcdef",MOD(INT(D4/16),16)+1,1)&MID("0123456789abcdef",MOD(MOD(D4,16),16)+1,1),"") -> 65 | F4: =IF(D4<>"",MOD(INT(D4/2^7),2),"") -> 0 | G4: =IF(D4<>"",MOD(INT(D4/2^6),2),"") -> 1 | H4: =IF(D4<>"",MOD(INT(D4/2^5),2),"") -> 1 | I4: =IF(D4<>"",MOD(INT(D4/2^4),2),"") -> 0 | J4: =IF(D4<>"",MOD(INT(D4/2^3),2),"") -> 0 | K4: =IF(D4<>"",MOD(INT(D4/2^2),2),"") -> 1 | L4: =IF(D4<>"",MOD(INT(D4/2^1),2),"") -> 0 | M4: =IF(D4<>"",MOD(INT(D4/2^0),2),"") -> 1
B5: 3 | C5: =IF(LEN('🔐 SHA-256'!B5)>=3,MID('🔐 SHA-256'!B5,3,1),"-") -> l | D5: =IF(C5<>"-",CODE(C5),"") -> 108 | E5: =IF(D5<>"",MID("0123456789abcdef",MOD(INT(D5/16),16)+1,1)&MID("0123456789abcdef",MOD(MOD(D5,16),16)+1,1),"") -> 6c | F5: =IF(D5<>"",MOD(INT(D5/2^7),2),"") -> 0 | G5: =IF(D5<>"",MOD(INT(D5/2^6),2),"") -> 1 | H5: =IF(D5<>"",MOD(INT(D5/2^5),2),"") -> 1 | I5: =IF(D5<>"",MOD(INT(D5/2^4),2),"") -> 0 | J5: =IF(D5<>"",MOD(INT(D5/2^3),2),"") -> 1 | K5: =IF(D5<>"",MOD(INT(D5/2^2),2),"") -> 1 | L5: =IF(D5<>"",MOD(INT(D5/2^1),2),"") -> 0 | M5: =IF(D5<>"",MOD(INT(D5/2^0),2),"") -> 0
B6: 4 | C6: =IF(LEN('🔐 SHA-256'!B5)>=4,MID('🔐 SHA-256'!B5,4,1),"-") -> l | D6: =IF(C6<>"-",CODE(C6),"") -> 108 | E6: =IF(D6<>"",MID("0123456789abcdef",MOD(INT(D6/16),16)+1,1)&MID("0123456789abcdef",MOD(MOD(D6,16),16)+1,1),"") -> 6c | F6: =IF(D6<>"",MOD(INT(D6/2^7),2),"") -> 0 | G6: =IF(D6<>"",MOD(INT(D6/2^6),2),"") -> 1 | H6: =IF(D6<>"",MOD(INT(D6/2^5),2),"") -> 1 | I6: =IF(D6<>"",MOD(INT(D6/2^4),2),"") -> 0 | J6: =IF(D6<>"",MOD(INT(D6/2^3),2),"") -> 1 | K6: =IF(D6<>"",MOD(INT(D6/2^2),2),"") -> 1 | L6: =IF(D6<>"",MOD(INT(D6/2^1),2),"") -> 0 | M6: =IF(D6<>"",MOD(INT(D6/2^0),2),"") -> 0
B7: 5 | C7: =IF(LEN('🔐 SHA-256'!B5)>=5,MID('🔐 SHA-256'!B5,5,1),"-") -> o | D7: =IF(C7<>"-",CODE(C7),"") -> 111 | E7: =IF(D7<>"",MID("0123456789abcdef",MOD(INT(D7/16),16)+1,1)&MID("0123456789abcdef",MOD(MOD(D7,16),16)+1,1),"") -> 6f | F7: =IF(D7<>"",MOD(INT(D7/2^7),2),"") -> 0 | G7: =IF(D7<>"",MOD(INT(D7/2^6),2),"") -> 1 | H7: =IF(D7<>"",MOD(INT(D7/2^5),2),"") -> 1 | I7: =IF(D7<>"",MOD(INT(D7/2^4),2),"") -> 0 | J7: =IF(D7<>"",MOD(INT(D7/2^3),2),"") -> 1 | K7: =IF(D7<>"",MOD(INT(D7/2^2),2),"") -> 1 | L7: =IF(D7<>"",MOD(INT(D7/2^1),2),"") -> 1 | M7: =IF(D7<>"",MOD(INT(D7/2^0),2),"") -> 1
B8: 6 | C8: =IF(LEN('🔐 SHA-256'!B5)>=6,MID('🔐 SHA-256'!B5,6,1),"-") -> - | D8: =IF(C8<>"-",CODE(C8),"") | E8: =IF(D8<>"",MID("0123456789abcdef",MOD(INT(D8/16),16)+1,1)&MID("0123456789abcdef",MOD(MOD(D8,16),16)+1,1),"") | F8: =IF(D8<>"",MOD(INT(D8/2^7),2),"") | G8: =IF(D8<>"",MOD(INT(D8/2^6),2),"") | H8: =IF(D8<>"",MOD(INT(D8/2^5),2),"") | I8: =IF(D8<>"",MOD(INT(D8/2^4),2),"") | J8: =IF(D8<>"",MOD(INT(D8/2^3),2),"") | K8: =IF(D8<>"",MOD(INT(D8/2^2),2),"") | L8: =IF(D8<>"",MOD(INT(D8/2^1),2),"") | M8: =IF(D8<>"",MOD(INT(D8/2^0),2),"")
B9: 7 | C9: =IF(LEN('🔐 SHA-256'!B5)>=7,MID('🔐 SHA-256'!B5,7,1),"-") -> - | D9: =IF(C9<>"-",CODE(C9),"") | E9: =IF(D9<>"",MID("0123456789abcdef",MOD(INT(D9/16),16)+1,1)&MID("0123456789abcdef",MOD(MOD(D9,16),16)+1,1),"") | F9: =IF(D9<>"",MOD(INT(D9/2^7),2),"") | G9: =IF(D9<>"",MOD(INT(D9/2^6),2),"") | H9: =IF(D9<>"",MOD(INT(D9/2^5),2),"") | I9: =IF(D9<>"",MOD(INT(D9/2^4),2),"") | J9: =IF(D9<>"",MOD(INT(D9/2^3),2),"") | K9: =IF(D9<>"",MOD(INT(D9/2^2),2),"") | L9: =IF(D9<>"",MOD(INT(D9/2^1),2),"") | M9: =IF(D9<>"",MOD(INT(D9/2^0),2),"")
B10: Input length (bytes): | E10: =LEN('🔐 SHA-256'!B5) -> 5 | F10: Length in bits: | I10: =E10*8 -> 40

Sheet 📦 SHA-256 Constants
B1: 📦 SHA-256 Constants — K[i] (from cube roots of primes)
B2: K[i] = floor(2³² × ∛p[i]) где p[i] — i-е простое число. Начальные значения H0..H7 = floor(2³² × √p[i]). Используются в каждом из 64 раундов сжатия.
B3: i | C3: K[i] decimal | D3: K[i] hex | E3: Простое | G3: i | H3: K[i] decimal | I3: K[i] hex | J3: Простое
B4: 0 | C4: 1116352408 | D4: 0x428A2F98 | E4: 2
B5: 1 | C5: 1899447441 | D5: 0x71374491 | E5: 3
B6: 2 | C6: 3049323471 | D6: 0xB5C0FBCF | E6: 5
B7: 3 | C7: 3921009573 | D7: 0xE9B5DBA5 | E7: 7
B8: 4 | C8: 961987163 | D8: 0x3956C25B | E8: 11
B9: 5 | C9: 1508970993 | D9: 0x59F111F1 | E9: 13
B10: 6 | C10: 2453635748 | D10: 0x923F82A4 | E10: 17
B11: 7 | C11: 2870763221 | D11: 0xAB1C5ED5 | E11: 19
B12: 8 | C12: 3624381080 | D12: 0xD807AA98 | E12: 23
B13: 9 | C13: 310598401 | D13: 0x12835B01 | E13: 29
B14: 10 | C14: 607225278 | D14: 0x243185BE | E14: 31
B15: 11 | C15: 1426881987 | D15: 0x550C7DC3 | E15: 37
... B67: 63 | C67: 3329325298 | D67: 0xC67178F2 | E67: 311

Sheet ⚙️ Computation
B1: ⚙️ Computation SHA-256 — 64 раунда сжатия + расписание сообщения W[i] | AM1: Message Schedule W[i]
B2: SHA-256 HASH: | E2: =LOWER(MID("0123456789abcdef",MOD(INT((MOD(INT(C70/256^3),256))/16),16)+1,1)&MID("0123456789abcdef",MOD(MOD((MOD(INT(C70/256^3),256)),16),16)+1,1)&MID("0123456789abcdef",MOD(INT((MOD(INT(C70/256^2),256))/16),16)+1,1)&MID("0123456789abcdef",MOD(MOD((MOD(INT(C70/256^2),256)),16),16)+1,1)&MID("0123456789abcdef",MOD(INT((MOD(INT(C70/256^1),256))/16),16)+1,1)&MID("0123456789abcdef",MOD(MOD((MOD(INT(C70/256^1),256)),16),16)+1,1)&MID("0123456789abcdef",MOD(INT((MOD(INT(C70/256^0),256))/16),16)+1,1)&MID("0123456789abcdef",MOD(MOD((MOD(INT(C70/256^0),256)),16),16)+1,1)&MID("0123456789abcdef",MOD(INT((MOD(INT(D70/256^3),256))/16),16)+1,1)&MID("0123456789abcdef",MOD(MOD((MOD(INT(D70/256^3),256)),16),16)+1,1)&MID("0123456789abcdef",MOD(INT((MOD(INT(D70/256^2),256))/16),16)+1,1)&MID("0123456789abcdef",MOD(MOD((MOD(INT(D70/256^2),256)),16),16)+1,1)&MID("0123456789abcdef",MOD(INT((MOD(INT(D70/256^1),256))/16),16)+1,1)&MID("0123456789abcdef",MOD(MOD((MOD(INT(D70/256^1),256)),16),16)+1,1)&MID("0123456789abcdef",MOD(INT((MOD(INT(D70/256^0),256))/16),16)+1,1)&MID("0123456789abcdef",MOD(MOD((MOD(INT(D70/256^0),256)),16),16)+1,1)&MID("0123456789abcdef",MOD(INT((MOD(INT(E70/256^3),256))/16),16)+1,1)&MID("0123456789abcdef",MOD(MOD((MOD(INT(E70/256^3),256)),16),16)+1,1)&MID("0123456789abcdef",MOD(INT((MOD(INT(E70/256^2),256))/16),16)+1,1)&MID("0123456789abcdef",MOD(MOD((MOD(INT(E70/256^2),256)),16),16)+1,1)&MID("0123456789abcdef",MOD(INT((MOD(INT(E70/256^1),256))/16),16)+1,1)&MID("0123456789abcdef",MOD(MOD((MOD(INT(E70/256^1),256)),16),16)+1,1)&MID("0123456789abcdef",MOD(INT((MOD(INT(E70/256^0),256))/16),16)+1,1)&MID("0123456789abcdef",MOD(MOD((MOD(INT(E70/256^0),256)),16),16)+1,1)&MID("0123456789abcdef",MOD(INT((MOD(INT(F70/256^3),256))/16),16)+1,1)&MID("0123456789abcdef",MOD(MOD((MOD(INT(F70/256^3),256)),16),16)+1,1)&MID("0123456789abcdef",MOD(INT((MOD(INT(F70/256^2),256))/16),16)+1,1)&MID("0123456789abcdef",MOD(MOD((MOD(INT(F70/256^2),256)),16),16)+1,1)&MID("0123456789abcdef",MOD(INT((MOD(INT(F70/256^1),256))/16),16)+1,1)&MID("0123456789abcdef",MOD(MOD((MOD(INT(F70/256^1),256)),16),16)+1,1)&MID("0123456789abcdef",MOD(INT((MOD(INT(F70/256^0),256))/16),16)+1,1)&MID("0123456789abcdef",MOD(MOD((MOD(INT(F70/256^0),256)),16),16)+1,1)&MID("0123456789abcdef",MOD(INT((MOD(INT(G70/256^3),256))/16),16)+1,1)&MID("0123456789abcdef",MOD(MOD((MOD(INT(G70/256^3),256)),16),16)+1,1)&MID("0123456789abcdef",MOD(INT((MOD(INT(G70/256^2),256))/16),16)+1,1)&MID("0123456789abcdef",MOD(MOD((MOD(INT(G70/256^2),256)),16),16)+1,1)&MID("0123456789abcdef",MOD(INT((MOD(INT(G70/256^1),256))/16),16)+1,1)&MID("0123456789abcdef",MOD(MOD((MOD(INT(G70/256^1),256)),16),16)+1,1)&MID("0123456789abcdef",MOD(INT((MOD(INT(G70/256^0),256))/16),16)+1,1)&MID("0123456789abcdef",MOD(MOD((MOD(INT(G70/256^0),256)),16),16)+1,1)&MID("0123456789abcdef",MOD(INT((MOD(INT(H70/256^3),256))/16),16)+1,1)&MID("0123456789abcdef",MOD(MOD((MOD(INT(H70/256^3),256)),16),16)+1,1)&MID("0123456789abcdef",MOD(INT((MOD(INT(H70/256^2),256))/16),16)+1,1)&MID("0123456789abcdef",MOD(MOD((MOD(INT(H70/256^2),256)),16),16)+1,1)&MID("0123456789abcdef",MOD(INT((MOD(INT(H70/256^1),256))/16),16)+1,1)&MID("0123456789abcdef",MOD(MOD((MOD(INT(H70/256^1),256)),16),16)+1,1)&MID("0123456789abcdef",MOD(INT((MOD(INT(H70/256^0),256))/16),16)+1,1)&MID("0123456789abcdef",MOD(MOD((MOD(INT(H70/256^0),256)),16),16)+1,1)&MID("0123456789abcdef",MOD(INT((MOD(INT(I70/256^3),256))/16),16)+1,1)&MID("0123456789abcdef",MOD(MOD((MOD(INT(I70/256^3),256)),16),16)+1,1)&MID("0123456789abcdef",MOD(INT((MOD(INT(I70/256^2),256))/16),16)+1,1)&MID("0123456789abcdef",MOD(MOD((MOD(INT(I70/256^2),256)),16),16)+1,1)&MID("0123456789abcdef",MOD(INT((MOD(INT(I70/256^1),256))/16),16)+1,1)&MID("0123456789abcdef",MOD(MOD((MOD(INT(I70/256^1),256)),16),16)+1,1)&MID("0123456789abcdef",MOD(INT((MOD(INT(I70/256^0),256))/16),16)+1,1)&MID("0123456789abcdef",MOD(MOD((MOD(INT(I70/256^0),256)),16),16)+1,1)&MID("0123456789abcdef",MOD(INT((MOD(INT(J70/256^3),256))/16),16)+1,1)&MID("0123456789abcdef",MOD(MOD((MOD(INT(J70/256^3),256)),16),16)+1,1)&MID("0123456789abcdef",MOD(INT((MOD(INT(J70/256^2),256))/16),16)+1,1)&MID("0123456789abcdef",MOD(MOD((MOD(INT(J70/256^2),256)),16),16)+1,1)&MID("0123456789abcdef",MOD(INT((MOD(INT(J70/256^1),256))/16),16)+1,1)&MID("0123456789abcdef",MOD(MOD((MOD(INT(J70/256^1),256)),16),16)+1,1)&MID("0123456789abcdef",MOD(INT((MOD(INT(J70/256^0),256))/16),16)+1,1)&MID("0123456789abcdef",MOD(MOD((MOD(INT(J70/256^0),256)),16),16)+1,1)) -> 2cf24dba5fb0a30e26e83b2ac5b9e29e1b161e5c1fa7425e73043362938b9824
B3: Each step: S1=XOR3(ROTR(e,6),ROTR(e,11),ROTR(e,25)) Ch=AND(e,f)+AND(¬e,g) temp1=ADD32(h,S1,Ch,K[i],W[i]) S0=XOR3(ROTR(a,2),ROTR(a,13),ROTR(a,22)) Maj=AND(a,b)+AND(a,c)+AND(b,c)−2·AND(AND(a,b),AND(b,c)) temp2=ADD32(S0,Maj) | a..h — 8 переменных состояния
B4: Step | C4: a | D4: b | E4: c | F4: d | G4: e | H4: f | I4: g | J4: h | K4: AN(e,f) | L4: AN(¬e,g) | M4: Ch | N4: AN(a,b) | O4: AN(a,c) | P4: AN(b,c) | Q4: AN(ab,bc) | R4: Maj | S4: ROTR(e,6) | T4: ROTR(e,11) | U4: ROTR(e,25) | V4: AN(r6,r11) | W4: XOR(r6,r11) | X4: AN(xr,r25) | Y4: S1 | Z4: ROTR(a,2) | AA4: ROTR(a,13) | AB4: ROTR(a,22) | AC4: AN(r2,r13) | AD4: XOR(r2,r13) | AE4: AN(xr,r22) | AF4: S0 | AG4: temp1 | AH4: temp2 | AI4: W[i] | AJ4: K[i] | AK4: Note | AM4: i | AN4: W[i] | AO4: r7=ROTR(W-15,7) | AP4: AND(r7,r18) | AQ4: s0 | AR4: r17=ROTR(W-2,17) | AS4: r19=ROTR(W-2,19) | AT4: AND(r17,r19) | AU4: s1
B5: INIT | C5: 1779033703 | D5: 3144134277 | E5: 1013904242 | F5: 2773480762 | G5: 1359893119 | H5: 2600822924 | I5: 528734635 | J5: 1541459225 | K5: a₀..h₀ = H0..H7 (дробные части √первых 8 простых чисел) | AM5: 0 | AN5: =(IF(LEN('🔐 SHA-256'!B5)>0,CODE(MID('🔐 SHA-256'!B5,1,1)),IF(LEN('🔐 SHA-256'!B5)=0,128,0)))*16777216+(IF(LEN('🔐 SHA-256'!B5)>1,CODE(MID('🔐 SHA-256'!B5,2,1)),IF(LEN('🔐 SHA-256'!B5)=1,128,0)))*65536+(IF(LEN('🔐 SHA-256'!B5)>2,CODE(MID('🔐 SHA-256'!B5,3,1)),IF(LEN('🔐 SHA-256'!B5)=2,128,0)))*256+(IF(LEN('🔐 SHA-256'!B5)>3,CODE(MID('🔐 SHA-256'!B5,4,1)),IF(LEN('🔐 SHA-256'!B5)=3,128,0))) -> 1751477356 | AO5: — | AP5: — | AQ5: — | AR5: — | AS5: — | AT5: — | AU5: —
B6: 1 | C6: =MOD(AG6+AH6,4294967296) -> 1684927673 | D6: =C5 -> 1779033703 | E6: =D5 -> 3144134277 | F6: =E5 -> 1013904242 | G6: =MOD(F5+AG6,4294967296) -> 19746574 | H6: =G5 -> 1359893119 | I6: =H5 -> 2600822924 | J6: =I5 -> 528734635 | K6: =((MOD(INT(MOD(INT((G5)/1),256)/2^0),2)*MOD(INT(MOD(INT((H5)/1),256)/2^0),2)*1+MOD(INT(MOD(INT((G5)/1),256)/2^1),2)*MOD(INT(MOD(INT((H5)/1),256)/2^1),2)*2+MOD(INT(MOD(INT((G5)/1),256)/2^2),2)*MOD(INT(MOD(INT((H5)/1),256)/2^2),2)*4+MOD(INT(MOD(INT((G5)/1),256)/2^3),2)*MOD(INT(MOD(INT((H5)/1),256)/2^3),2)*8+MOD(INT(MOD(INT((G5)/1),256)/2^4),2)*MOD(INT(MOD(INT((H5)/1),256)/2^4),2)*16+MOD(INT(MOD(INT((G5)/1),256)/2^5),2)*MOD(INT(MOD(INT((H5)/1),256)/2^5),2)*32+MOD(INT(MOD(INT((G5)/1),256)/2^6),2)*MOD(INT(MOD(INT((H5)/1),256)/2^6),2)*64+MOD(INT(MOD(INT((G5)/1),256)/2^7),2)*MOD(INT(MOD(INT((H5)/1),256)/2^7),2)*128)*1+(MOD(INT(MOD(INT((G5)/256),256)/2^0),2)*MOD(INT(MOD(INT((H5)/256),256)/2^0),2)*1+MOD(INT(MOD(INT((G5)/256),256)/2^1),2)*MOD(INT(MOD(INT((H5)/256),256)/2^1),2)*2+MOD(INT(MOD(INT((G5)/256),256)/2^2),2)*MOD(INT(MOD(INT((H5)/256),256)/2^2),2)*4+MOD(INT(MOD(INT((G5)/256),256)/2^3),2)*MOD(INT(MOD(INT((H5)/256),256)/2^3),2)*8+MOD(INT(MOD(INT((G5)/256),256)/2^4),2)*MOD(INT(MOD(INT((H5)/256),256)/2^4),2)*16+MOD(INT(MOD(INT((G5)/256),256)/2^5),2)*MOD(INT(MOD(INT((H5)/256),256)/2^5),2)*32+MOD(INT(MOD(INT((G5)/256),256)/2^6),2)*MOD(INT(MOD(INT((H5)/256),256)/2^6),2)*64+MOD(INT(MOD(INT((G5)/256),256)/2^7),2)*MOD(INT(MOD(INT((H5)/256),256)/2^7),2)*128)*256+(MOD(INT(MOD(INT((G5)/65536),256)/2^0),2)*MOD(INT(MOD(INT((H5)/65536),256)/2^0),2)*1+MOD(INT(MOD(INT((G5)/65536),256)/2^1),2)*MOD(INT(MOD(INT((H5)/65536),256)/2^1),2)*2+MOD(INT(MOD(INT((G5)/65536),256)/2^2),2)*MOD(INT(MOD(INT((H5)/65536),256)/2^2),2)*4+MOD(INT(MOD(INT((G5)/65536),256)/2^3),2)*MOD(INT(MOD(INT((H5)/65536),256)/2^3),2)*8+MOD(INT(MOD(INT((G5)/65536),256)/2^4),2)*MOD(INT(MOD(INT((H5)/65536),256)/2^4),2)*16+MOD(INT(MOD(INT((G5)/65536),256)/2^5),2)*MOD(INT(MOD(INT((H5)/65536),256)/2^5),2)*32+MOD(INT(MOD(INT((G5)/65536),256)/2^6),2)*MOD(INT(MOD(INT((H5)/65536),256)/2^6),2)*64+MOD(INT(MOD(INT((G5)/65536),256)/2^7),2)*MOD(INT(MOD(INT((H5)/65536),256)/2^7),2)*128)*65536+(MOD(INT(MOD(INT((G5)/16777216),256)/2^0),2)*MOD(INT(MOD(INT((H5)/16777216),256)/2^0),2)*1+MOD(INT(MOD(INT((G5)/16777216),256)/2^1),2)*MOD(INT(MOD(INT((H5)/16777216),256)/2^1),2)*2+MOD(INT(MOD(INT((G5)/16777216),256)/2^2),2)*MOD(INT(MOD(INT((H5)/16777216),256)/2^2),2)*4+MOD(INT(MOD(INT((G5)/16777216),256)/2^3),2)*MOD(INT(MOD(INT((H5)/16777216),256)/2^3),2)*8+MOD(INT(MOD(INT((G5)/16777216),256)/2^4),2)*MOD(INT(MOD(INT((H5)/16777216),256)/2^4),2)*16+MOD(INT(MOD(INT((G5)/16777216),256)/2^5),2)*MOD(INT(MOD(INT((H5)/16777216),256)/2^5),2)*32+MOD(INT(MOD(INT((G5)/16777216),256)/2^6),2)*MOD(INT(MOD(INT((H5)/16777216),256)/2^6),2)*64+MOD(INT(MOD(INT((G5)/16777216),256)/2^7),2)*MOD(INT(MOD(INT((H5)/16777216),256)/2^7),2)*128)*16777216) -> 285491212 | L6: =((MOD(INT(MOD(INT(((4294967295-G5))/1),256)/2^0),2)*MOD(INT(MOD(INT((I5)/1),256)/2^0),2)*1+MOD(INT(MOD(INT(((4294967295-G5))/1),256)/2^1),2)*MOD(INT(MOD(INT((I5)/1),256)/2^1),2)*2+MOD(INT(MOD(INT(((4294967295-G5))/1),256)/2^2),2)*MOD(INT(MOD(INT((I5)/1),256)/2^2),2)*4+MOD(INT(MOD(INT(((4294967295-G5))/1),256)/2^3),2)*MOD(INT(MOD(INT((I5)/1),256)/2^3),2)*8+MOD(INT(MOD(INT(((4294967295-G5))/1),256)/2^4),2)*MOD(INT(MOD(INT((I5)/1),256)/2^4),2)*16+MOD(INT(MOD(INT(((4294967295-G5))/1),256)/2^5),2)*MOD(INT(MOD(INT((I5)/1),256)/2^5),2)*32+MOD(INT(MOD(INT(((4294967295-G5))/1),256)/2^6),2)*MOD(INT(MOD(INT((I5)/1),256)/2^6),2)*64+MOD(INT(MOD(INT(((4294967295-G5))/1),256)/2^7),2)*MOD(INT(MOD(INT((I5)/1),256)/2^7),2)*128)*1+(MOD(INT(MOD(INT(((4294967295-G5))/256),256)/2^0),2)*MOD(INT(MOD(INT((I5)/256),256)/2^0),2)*1+MOD(INT(MOD(INT(((4294967295-G5))/256),256)/2^1),2)*MOD(INT(MOD(INT((I5)/256),256)/2^1),2)*2+MOD(INT(MOD(INT(((4294967295-G5))/256),256)/2^2),2)*MOD(INT(MOD(INT((I5)/256),256)/2^2),2)*4+MOD(INT(MOD(INT(((4294967295-G5))/256),256)/2^3),2)*MOD(INT(MOD(INT((I5)/256),256)/2^3),2)*8+MOD(INT(MOD(INT(((4294967295-G5))/256),256)/2^4),2)*MOD(INT(MOD(INT((I5)/256),256)/2^4),2)*16+MOD(INT(MOD(INT(((4294967295-G5))/256),256)/2^5),2)*MOD(INT(MOD(INT((I5)/256),256)/2^5),2)*32+MOD(INT(MOD(INT(((4294967295-G5))/256),256)/2^6),2)*MOD(INT(MOD(INT((I5)/256),256)/2^6),2)*64+MOD(INT(MOD(INT(((4294967295-G5))/256),256)/2^7),2)*MOD(INT(MOD(INT((I5)/256),256)/2^7),2)*128)*256+(MOD(INT(MOD(INT(((4294967295-G5))/65536),256)/2^0),2)*MOD(INT(MOD(INT((I5)/65536),256)/2^0),2)*1+MOD(INT(MOD(INT(((4294967295-G5))/65536),256)/2^1),2)*MOD(INT(MOD(INT((I5)/65536),256)/2^1),2)*2+MOD(INT(MOD(INT(((4294967295-G5))/65536),256)/2^2),2)*MOD(INT(MOD(INT((I5)/65536),256)/2^2),2)*4+MOD(INT(MOD(INT(((4294967295-G5))/65536),256)/2^3),2)*MOD(INT(MOD(INT((I5)/65536),256)/2^3),2)*8+MOD(INT(MOD(INT(((4294967295-G5))/65536),256)/2^4),2)*MOD(INT(MOD(INT((I5)/65536),256)/2^4),2)*16+MOD(INT(MOD(INT(((4294967295-G5))/65536),256)/2^5),2)*MOD(INT(MOD(INT((I5)/65536),256)/2^5),2)*32+MOD(INT(MOD(INT(((4294967295-G5))/65536),256)/2^6),2)*MOD(INT(MOD(INT((I5)/65536),256)/2^6),2)*64+MOD(INT(MOD(INT(((4294967295-G5))/65536),256)/2^7),2)*MOD(INT(MOD(INT((I5)/65536),256)/2^7),2)*128)*65536+(MOD(INT(MOD(INT(((4294967295-G5))/16777216),256)/2^0),2)*MOD(INT(MOD(INT((I5)/16777216),256)/2^0),2)*1+MOD(INT(MOD(INT(((4294967295-G5))/16777216),256)/2^1),2)*MOD(INT(MOD(INT((I5)/16777216),256)/2^1),2)*2+MOD(INT(MOD(INT(((4294967295-G5))/16777216),256)/2^2),2)*MOD(INT(MOD(INT((I5)/16777216),256)/2^2),2)*4+MOD(INT(MOD(INT(((4294967295-G5))/16777216),256)/2^3),2)*MOD(INT(MOD(INT((I5)/16777216),256)/2^3),2)*8+MOD(INT(MOD(INT(((4294967295-G5))/16777216),256)/2^4),2)*MOD(INT(MOD(INT((I5)/16777216),256)/2^4),2)*16+MOD(INT(MOD(INT(((4294967295-G5))/16777216),256)/2^5),2)*MOD(INT(MOD(INT((I5)/16777216),256)/2^5),2)*32+MOD(INT(MOD(INT(((4294967295-G5))/16777216),256)/2^6),2)*MOD(INT(MOD(INT((I5)/16777216),256)/2^6),2)*64+MOD(INT(MOD(INT(((4294967295-G5))/16777216),256)/2^7),2)*MOD(INT(MOD(INT((I5)/16777216),256)/2^7),2)*128)*16777216) -> 243370368 | M6: =MOD(K6+L6,4294967296) -> 528861580 | N6: =((MOD(INT(MOD(INT((C5)/1),256)/2^0),2)*MOD(INT(MOD(INT((D5)/1),256)/2^0),2)*1+MOD(INT(MOD(INT((C5)/1),256)/2^1),2)*MOD(INT(MOD(INT((D5)/1),256)/2^1),2)*2+MOD(INT(MOD(INT((C5)/1),256)/2^2),2)*MOD(INT(MOD(INT((D5)/1),256)/2^2),2)*4+MOD(INT(MOD(INT((C5)/1),256)/2^3),2)*MOD(INT(MOD(INT((D5)/1),256)/2^3),2)*8+MOD(INT(MOD(INT((C5)/1),256)/2^4),2)*MOD(INT(MOD(INT((D5)/1),256)/2^4),2)*16+MOD(INT(MOD(INT((C5)/1),256)/2^5),2)*MOD(INT(MOD(INT((D5)/1),256)/2^5),2)*32+MOD(INT(MOD(INT((C5)/1),256)/2^6),2)*MOD(INT(MOD(INT((D5)/1),256)/2^6),2)*64+MOD(INT(MOD(INT((C5)/1),256)/2^7),2)*MOD(INT(MOD(INT((D5)/1),256)/2^7),2)*128)*1+(MOD(INT(MOD(INT((C5)/256),256)/2^0),2)*MOD(INT(MOD(INT((D5)/256),256)/2^0),2)*1+MOD(INT(MOD(INT((C5)/256),256)/2^1),2)*MOD(INT(MOD(INT((D5)/256),256)/2^1),2)*2+MOD(INT(MOD(INT((C5)/256),256)/2^2),2)*MOD(INT(MOD(INT((D5)/256),256)/2^2),2)*4+MOD(INT(MOD(INT((C5)/256),256)/2^3),2)*MOD(INT(MOD(INT((D5)/256),256)/2^3),2)*8+MOD(INT(MOD(INT((C5)/256),256)/2^4),2)*MOD(INT(MOD(INT((D5)/256),256)/2^4),2)*16+MOD(INT(MOD(INT((C5)/256),256)/2^5),2)*MOD(INT(MOD(INT((D5)/256),256)/2^5),2)*32+MOD(INT(MOD(INT((C5)/256),256)/2^6),2)*MOD(INT(MOD(INT((D5)/256),256)/2^6),2)*64+MOD(INT(MOD(INT((C5)/256),256)/2^7),2)*MOD(INT(MOD(INT((D5)/256),256)/2^7),2)*128)*256+(MOD(INT(MOD(INT((C5)/65536),256)/2^0),2)*MOD(INT(MOD(INT((D5)/65536),256)/2^0),2)*1+MOD(INT(MOD(INT((C5)/65536),256)/2^1),2)*MOD(INT(MOD(INT((D5)/65536),256)/2^1),2)*2+MOD(INT(MOD(INT((C5)/65536),256)/2^2),2)*MOD(INT(MOD(INT((D5)/65536),256)/2^2),2)*4+MOD(INT(MOD(INT((C5)/65536),256)/2^3),2)*MOD(INT(MOD(INT((D5)/65536),256)/2^3),2)*8+MOD(INT(MOD(INT((C5)/65536),256)/2^4),2)*MOD(INT(MOD(INT((D5)/65536),256)/2^4),2)*16+MOD(INT(MOD(INT((C5)/65536),256)/2^5),2)*MOD(INT(MOD(INT((D5)/65536),256)/2^5),2)*32+MOD(INT(MOD(INT((C5)/65536),256)/2^6),2)*MOD(INT(MOD(INT((D5)/65536),256)/2^6),2)*64+MOD(INT(MOD(INT((C5)/65536),256)/2^7),2)*MOD(INT(MOD(INT((D5)/65536),256)/2^7),2)*128)*65536+(MOD(INT(MOD(INT((C5)/16777216),256)/2^0),2)*MOD(INT(MOD(INT((D5)/16777216),256)/2^0),2)*1+MOD(INT(MOD(INT((C5)/16777216),256)/2^1),2)*MOD(INT(MOD(INT((D5)/16777216),256)/2^1),2)*2+MOD(INT(MOD(INT((C5)/16777216),256)/2^2),2)*MOD(INT(MOD(INT((D5)/16777216),256)/2^2),2)*4+MOD(INT(MOD(INT((C5)/16777216),256)/2^3),2)*MOD(INT(MOD(INT((D5)/16777216),256)/2^3),2)*8+MOD(INT(MOD(INT((C5)/16777216),256)/2^4),2)*MOD(INT(MOD(INT((D5)/16777216),256)/2^4),2)*16+MOD(INT(MOD(INT((C5)/16777216),256)/2^5),2)*MOD(INT(MOD(INT((D5)/16777216),256)/2^5),2)*32+MOD(INT(MOD(INT((C5)/16777216),256)/2^6),2)*MOD(INT(MOD(INT((D5)/16777216),256)/2^6),2)*64+MOD(INT(MOD(INT((C5)/16777216),256)/2^7),2)*MOD(INT(MOD(INT((D5)/16777216),256)/2^7),2)*128)*16777216) -> 704751109 | O6: =((MOD(INT(MOD(INT((C5)/1),256)/2^0),2)*MOD(INT(MOD(INT((E5)/1),256)/2^0),2)*1+MOD(INT(MOD(INT((C5)/1),256)/2^1),2)*MOD(INT(MOD(INT((E5)/1),256)/2^1),2)*2+MOD(INT(MOD(INT((C5)/1),256)/2^2),2)*MOD(INT(MOD(INT((E5)/1),256)/2^2),2)*4+MOD(INT(MOD(INT((C5)/1),256)/2^3),2)*MOD(INT(MOD(INT((E5)/1),256)/2^3),2)*8+MOD(INT(MOD(INT((C5)/1),256)/2^4),2)*MOD(INT(MOD(INT((E5)/1),256)/2^4),2)*16+MOD(INT(MOD(INT((C5)/1),256)/2^5),2)*MOD(INT(MOD(INT((E5)/1),256)/2^5),2)*32+MOD(INT(MOD(INT((C5)/1),256)/2^6),2)*MOD(INT(MOD(INT((E5)/1),256)/2^6),2)*64+MOD(INT(MOD(INT((C5)/1),256)/2^7),2)*MOD(INT(MOD(INT((E5)/1),256)/2^7),2)*128)*1+(MOD(INT(MOD(INT((C5)/256),256)/2^0),2)*MOD(INT(MOD(INT((E5)/256),256)/2^0),2)*1+MOD(INT(MOD(INT((C5)/256),256)/2^1),2)*MOD(INT(MOD(INT((E5)/256),256)/2^1),2)*2+MOD(INT(MOD(INT((C5)/256),256)/2^2),2)*MOD(INT(MOD(INT((E5)/256),256)/2^2),2)*4+MOD(INT(MOD(INT((C5)/256),256)/2^3),2)*MOD(INT(MOD(INT((E5)/256),256)/2^3),2)*8+MOD(INT(MOD(INT((C5)/256),256)/2^4),2)*MOD(INT(MOD(INT((E5)/256),256)/2^4),2)*16+MOD(INT(MOD(INT((C5)/256),256)/2^5),2)*MOD(INT(MOD(INT((E5)/256),256)/2^5),2)*32+MOD(INT(MOD(INT((C5)/256),256)/2^6),2)*MOD(INT(MOD(INT((E5)/256),256)/2^6),2)*64+MOD(INT(MOD(INT((C5)/256),256)/2^7),2)*MOD(INT(MOD(INT((E5)/256),256)/2^7),2)*128)*256+(MOD(INT(MOD(INT((C5)/65536),256)/2^0),2)*MOD(INT(MOD(INT((E5)/65536),256)/2^0),2)*1+MOD(INT(MOD(INT((C5)/65536),256)/2^1),2)*MOD(INT(MOD(INT((E5)/65536),256)/2^1),2)*2+MOD(INT(MOD(INT((C5)/65536),256)/2^2),2)*MOD(INT(MOD(INT((E5)/65536),256)/2^2),2)*4+MOD(INT(MOD(INT((C5)/65536),256)/2^3),2)*MOD(INT(MOD(INT((E5)/65536),256)/2^3),2)*8+MOD(INT(MOD(INT((C5)/65536),256)/2^4),2)*MOD(INT(MOD(INT((E5)/65536),256)/2^4),2)*16+MOD(INT(MOD(INT((C5)/65536),256)/2^5),2)*MOD(INT(MOD(INT((E5)/65536),256)/2^5),2)*32+MOD(INT(MOD(INT((C5)/65536),256)/2^6),2)*MOD(INT(MOD(INT((E5)/65536),256)/2^6),2)*64+MOD(INT(MOD(INT((C5)/65536),256)/2^7),2)*MOD(INT(MOD(INT((E5)/65536),256)/2^7),2)*128)*65536+(MOD(INT(MOD(INT((C5)/16777216),256)/2^0),2)*MOD(INT(MOD(INT((E5)/16777216),256)/2^0),2)*1+MOD(INT(MOD(INT((C5)/16777216),256)/2^1),2)*MOD(INT(MOD(INT((E5)/16777216),256)/2^1),2)*2+MOD(INT(MOD(INT((C5)/16777216),256)/2^2),2)*MOD(INT(MOD(INT((E5)/16777216),256)/2^2),2)*4+MOD(INT(MOD(INT((C5)/16777216),256)/2^3),2)*MOD(INT(MOD(INT((E5)/16777216),256)/2^3),2)*8+MOD(INT(MOD(INT((C5)/16777216),256)/2^4),2)*MOD(INT(MOD(INT((E5)/16777216),256)/2^4),2)*16+MOD(INT(MOD(INT((C5)/16777216),256)/2^5),2)*MOD(INT(MOD(INT((E5)/16777216),256)/2^5),2)*32+MOD(INT(MOD(INT((C5)/16777216),256)/2^6),2)*MOD(INT(MOD(INT((E5)/16777216),256)/2^6),2)*64+MOD(INT(MOD(INT((C5)/16777216),256)/2^7),2)*MOD(INT(MOD(INT((E5)/16777216),256)/2^7),2)*128)*16777216) -> 671670882 | P6: =((MOD(INT(MOD(INT((D5)/1),256)/2^0),2)*MOD(INT(MOD(INT((E5)/1),256)/2^0),2)*1+MOD(INT(MOD(INT((D5)/1),256)/2^1),2)*MOD(INT(MOD(INT((E5)/1),256)/2^1),2)*2+MOD(INT(MOD(INT((D5)/1),256)/2^2),2)*MOD(INT(MOD(INT((E5)/1),256)/2^2),2)*4+MOD(INT(MOD(INT((D5)/1),256)/2^3),2)*MOD(INT(MOD(INT((E5)/1),256)/2^3),2)*8+MOD(INT(MOD(INT((D5)/1),256)/2^4),2)*MOD(INT(MOD(INT((E5)/1),256)/2^4),2)*16+MOD(INT(MOD(INT((D5)/1),256)/2^5),2)*MOD(INT(MOD(INT((E5)/1),256)/2^5),2)*32+MOD(INT(MOD(INT((D5)/1),256)/2^6),2)*MOD(INT(MOD(INT((E5)/1),256)/2^6),2)*64+MOD(INT(MOD(INT((D5)/1),256)/2^7),2)*MOD(INT(MOD(INT((E5)/1),256)/2^7),2)*128)*1+(MOD(INT(MOD(INT((D5)/256),256)/2^0),2)*MOD(INT(MOD(INT((E5)/256),256)/2^0),2)*1+MOD(INT(MOD(INT((D5)/256),256)/2^1),2)*MOD(INT(MOD(INT((E5)/256),256)/2^1),2)*2+MOD(INT(MOD(INT((D5)/256),256)/2^2),2)*MOD(INT(MOD(INT((E5)/256),256)/2^2),2)*4+MOD(INT(MOD(INT((D5)/256),256)/2^3),2)*MOD(INT(MOD(INT((E5)/256),256)/2^3),2)*8+MOD(INT(MOD(INT((D5)/256),256)/2^4),2)*MOD(INT(MOD(INT((E5)/256),256)/2^4),2)*16+MOD(INT(MOD(INT((D5)/256),256)/2^5),2)*MOD(INT(MOD(INT((E5)/256),256)/2^5),2)*32+MOD(INT(MOD(INT((D5)/256),256)/2^6),2)*MOD(INT(MOD(INT((E5)/256),256)/2^6),2)*64+MOD(INT(MOD(INT((D5)/256),256)/2^7),2)*MOD(INT(MOD(INT((E5)/256),256)/2^7),2)*128)*256+(MOD(INT(MOD(INT((D5)/65536),256)/2^0),2)*MOD(INT(MOD(INT((E5)/65536),256)/2^0),2)*1+MOD(INT(MOD(INT((D5)/65536),256)/2^1),2)*MOD(INT(MOD(INT((E5)/65536),256)/2^1),2)*2+MOD(INT(MOD(INT((D5)/65536),256)/2^2),2)*MOD(INT(MOD(INT((E5)/65536),256)/2^2),2)*4+MOD(INT(MOD(INT((D5)/65536),256)/2^3),2)*MOD(INT(MOD(INT((E5)/65536),256)/2^3),2)*8+MOD(INT(MOD(INT((D5)/65536),256)/2^4),2)*MOD(INT(MOD(INT((E5)/65536),256)/2^4),2)*16+MOD(INT(MOD(INT((D5)/65536),256)/2^5),2)*MOD(INT(MOD(INT((E5)/65536),256)/2^5),2)*32+MOD(INT(MOD(INT((D5)/65536),256)/2^6),2)*MOD(INT(MOD(INT((E5)/65536),256)/2^6),2)*64+MOD(INT(MOD(INT((D5)/65536),256)/2^7),2)*MOD(INT(MOD(INT((E5)/65536),256)/2^7),2)*128)*65536+(MOD(INT(MOD(INT((D5)/16777216),256)/2^0),2)*MOD(INT(MOD(INT((E5)/16777216),256)/2^0),2)*1+MOD(INT(MOD(INT((D5)/16777216),256)/2^1),2)*MOD(INT(MOD(INT((E5)/16777216),256)/2^1),2)*2+MOD(INT(MOD(INT((D5)/16777216),256)/2^2),2)*MOD(INT(MOD(INT((E5)/16777216),256)/2^2),2)*4+MOD(INT(MOD(INT((D5)/16777216),256)/2^3),2)*MOD(INT(MOD(INT((E5)/16777216),256)/2^3),2)*8+MOD(INT(MOD(INT((D5)/16777216),256)/2^4),2)*MOD(INT(MOD(INT((E5)/16777216),256)/2^4),2)*16+MOD(INT(MOD(INT((D5)/16777216),256)/2^5),2)*MOD(INT(MOD(INT((E5)/16777216),256)/2^5),2)*32+MOD(INT(MOD(INT((D5)/16777216),256)/2^6),2)*MOD(INT(MOD(INT((E5)/16777216),256)/2^6),2)*64+MOD(INT(MOD(INT((D5)/16777216),256)/2^7),2)*MOD(INT(MOD(INT((E5)/16777216),256)/2^7),2)*128)*16777216) -> 946250240 | Q6: =((MOD(INT(MOD(INT((N6)/1),256)/2^0),2)*MOD(INT(MOD(INT((P6)/1),256)/2^0),2)*1+MOD(INT(MOD(INT((N6)/1),256)/2^1),2)*MOD(INT(MOD(INT((P6)/1),256)/2^1),2)*2+MOD(INT(MOD(INT((N6)/1),256)/2^2),2)*MOD(INT(MOD(INT((P6)/1),256)/2^2),2)*4+MOD(INT(MOD(INT((N6)/1),256)/2^3),2)*MOD(INT(MOD(INT((P6)/1),256)/2^3),2)*8+MOD(INT(MOD(INT((N6)/1),256)/2^4),2)*MOD(INT(MOD(INT((P6)/1),256)/2^4),2)*16+MOD(INT(MOD(INT((N6)/1),256)/2^5),2)*MOD(INT(MOD(INT((P6)/1),256)/2^5),2)*32+MOD(INT(MOD(INT((N6)/1),256)/2^6),2)*MOD(INT(MOD(INT((P6)/1),256)/2^6),2)*64+MOD(INT(MOD(INT((N6)/1),256)/2^7),2)*MOD(INT(MOD(INT((P6)/1),256)/2^7),2)*128)*1+(MOD(INT(MOD(INT((N6)/256),256)/2^0),2)*MOD(INT(MOD(INT((P6)/256),256)/2^0),2)*1+MOD(INT(MOD(INT((N6)/256),256)/2^1),2)*MOD(INT(MOD(INT((P6)/256),256)/2^1),2)*2+MOD(INT(MOD(INT((N6)/256),256)/2^2),2)*MOD(INT(MOD(INT((P6)/256),256)/2^2),2)*4+MOD(INT(MOD(INT((N6)/256),256)/2^3),2)*MOD(INT(MOD(INT((P6)/256),256)/2^3),2)*8+MOD(INT(MOD(INT((N6)/256),256)/2^4),2)*MOD(INT(MOD(INT((P6)/256),256)/2^4),2)*16+MOD(INT(MOD(INT((N6)/256),256)/2^5),2)*MOD(INT(MOD(INT((P6)/256),256)/2^5),2)*32+MOD(INT(MOD(INT((N6)/256),256)/2^6),2)*MOD(INT(MOD(INT((P6)/256),256)/2^6),2)*64+MOD(INT(MOD(INT((N6)/256),256)/2^7),2)*MOD(INT(MOD(INT((P6)/256),256)/2^7),2)*128)*256+(MOD(INT(MOD(INT((N6)/65536),256)/2^0),2)*MOD(INT(MOD(INT((P6)/65536),256)/2^0),2)*1+MOD(INT(MOD(INT((N6)/65536),256)/2^1),2)*MOD(INT(MOD(INT((P6)/65536),256)/2^1),2)*2+MOD(INT(MOD(INT((N6)/65536),256)/2^2),2)*MOD(INT(MOD(INT((P6)/65536),256)/2^2),2)*4+MOD(INT(MOD(INT((N6)/65536),256)/2^3),2)*MOD(INT(MOD(INT((P6)/65536),256)/2^3),2)*8+MOD(INT(MOD(INT((N6)/65536),256)/2^4),2)*MOD(INT(MOD(INT((P6)/65536),256)/2^4),2)*16+MOD(INT(MOD(INT((N6)/65536),256)/2^5),2)*MOD(INT(MOD(INT((P6)/65536),256)/2^5),2)*32+MOD(INT(MOD(INT((N6)/65536),256)/2^6),2)*MOD(INT(MOD(INT((P6)/65536),256)/2^6),2)*64+MOD(INT(MOD(INT((N6)/65536),256)/2^7),2)*MOD(INT(MOD(INT((P6)/65536),256)/2^7),2)*128)*65536+(MOD(INT(MOD(INT((N6)/16777216),256)/2^0),2)*MOD(INT(MOD(INT((P6)/16777216),256)/2^0),2)*1+MOD(INT(MOD(INT((N6)/16777216),256)/2^1),2)*MOD(INT(MOD(INT((P6)/16777216),256)/2^1),2)*2+MOD(INT(MOD(INT((N6)/16777216),256)/2^2),2)*MOD(INT(MOD(INT((P6)/16777216),256)/2^2),2)*4+MOD(INT(MOD(INT((N6)/16777216),256)/2^3),2)*MOD(INT(MOD(INT((P6)/16777216),256)/2^3),2)*8+MOD(INT(MOD(INT((N6)/16777216),256)/2^4),2)*MOD(INT(MOD(INT((P6)/16777216),256)/2^4),2)*16+MOD(INT(MOD(INT((N6)/16777216),256)/2^5),2)*MOD(INT(MOD(INT((P6)/16777216),256)/2^5),2)*32+MOD(INT(MOD(INT((N6)/16777216),256)/2^6),2)*MOD(INT(MOD(INT((P6)/16777216),256)/2^6),2)*64+MOD(INT(MOD(INT((N6)/16777216),256)/2^7),2)*MOD(INT(MOD(INT((P6)/16777216),256)/2^7),2)*128)*16777216) -> 671130112 | R6: =MOD(N6+O6+P6-2*Q6,4294967296) -> 980412007 | S6: =MOD(MOD(G5,2^6)*2^26+INT(G5/2^6),4294967296) -> 4249106761 | T6: =MOD(MOD(G5,2^11)*2^21+INT(G5/2^11),4294967296) -> 1340744138 | U6: =MOD(MOD(G5,2^25)*2^7+INT(G5/2^25),4294967296) -> 2267627432 | V6: =((MOD(INT(MOD(INT((S6)/1),256)/2^0),2)*MOD(INT(MOD(INT((T6)/1),256)/2^0),2)*1+MOD(INT(MOD(INT((S6)/1),256)/2^1),2)*MOD(INT(MOD(INT((T6)/1),256)/2^1),2)*2+MOD(INT(MOD(INT((S6)/1),256)/2^2),2)*MOD(INT(MOD(INT((T6)/1),256)/2^2),2)*4+MOD(INT(MOD(INT((S6)/1),256)/2^3),2)*MOD(INT(MOD(INT((T6)/1),256)/2^3),2)*8+MOD(INT(MOD(INT((S6)/1),256)/2^4),2)*MOD(INT(MOD(INT((T6)/1),256)/2^4),2)*16+MOD(INT(MOD(INT((S6)/1),256)/2^5),2)*MOD(INT(MOD(INT((T6)/1),256)/2^5),2)*32+MOD(INT(MOD(INT((S6)/1),256)/2^6),2)*MOD(INT(MOD(INT((T6)/1),256)/2^6),2)*64+MOD(INT(MOD(INT((S6)/1),256)/2^7),2)*MOD(INT(MOD(INT((T6)/1),256)/2^7),2)*128)*1+(MOD(INT(MOD(INT((S6)/256),256)/2^0),2)*MOD(INT(MOD(INT((T6)/256),256)/2^0),2)*1+MOD(INT(MOD(INT((S6)/256),256)/2^1),2)*MOD(INT(MOD(INT((T6)/256),256)/2^1),2)*2+MOD(INT(MOD(INT((S6)/256),256)/2^2),2)*MOD(INT(MOD(INT((T6)/256),256)/2^2),2)*4+MOD(INT(MOD(INT((S6)/256),256)/2^3),2)*MOD(INT(MOD(INT((T6)/256),256)/2^3),2)*8+MOD(INT(MOD(INT((S6)/256),256)/2^4),2)*MOD(INT(MOD(INT((T6)/256),256)/2^4),2)*16+MOD(INT(MOD(INT((S6)/256),256)/2^5),2)*MOD(INT(MOD(INT((T6)/256),256)/2^5),2)*32+MOD(INT(MOD(INT((S6)/256),256)/2^6),2)*MOD(INT(MOD(INT((T6)/256),256)/2^6),2)*64+MOD(INT(MOD(INT((S6)/256),256)/2^7),2)*MOD(INT(MOD(INT((T6)/256),256)/2^7),2)*128)*256+(MOD(INT(MOD(INT((S6)/65536),256)/2^0),2)*MOD(INT(MOD(INT((T6)/65536),256)/2^0),2)*1+MOD(INT(MOD(INT((S6)/65536),256)/2^1),2)*MOD(INT(MOD(INT((T6)/65536),256)/2^1),2)*2+MOD(INT(MOD(INT((S6)/65536),256)/2^2),2)*MOD(INT(MOD(INT((T6)/65536),256)/2^2),2)*4+MOD(INT(MOD(INT((S6)/65536),256)/2^3),2)*MOD(INT(MOD(INT((T6)/65536),256)/2^3),2)*8+MOD(INT(MOD(INT((S6)/65536),256)/2^4),2)*MOD(INT(MOD(INT((T6)/65536),256)/2^4),2)*16+MOD(INT(MOD(INT((S6)/65536),256)/2^5),2)*MOD(INT(MOD(INT((T6)/65536),256)/2^5),2)*32+MOD(INT(MOD(INT((S6)/65536),256)/2^6),2)*MOD(INT(MOD(INT((T6)/65536),256)/2^6),2)*64+MOD(INT(MOD(INT((S6)/65536),256)/2^7),2)*MOD(INT(MOD(INT((T6)/65536),256)/2^7),2)*128)*65536+(MOD(INT(MOD(INT((S6)/16777216),256)/2^0),2)*MOD(INT(MOD(INT((T6)/16777216),256)/2^0),2)*1+MOD(INT(MOD(INT((S6)/16777216),256)/2^1),2)*MOD(INT(MOD(INT((T6)/16777216),256)/2^1),2)*2+MOD(INT(MOD(INT((S6)/16777216),256)/2^2),2)*MOD(INT(MOD(INT((T6)/16777216),256)/2^2),2)*4+MOD(INT(MOD(INT((S6)/16777216),256)/2^3),2)*MOD(INT(MOD(INT((T6)/16777216),256)/2^3),2)*8+MOD(INT(MOD(INT((S6)/16777216),256)/2^4),2)*MOD(INT(MOD(INT((T6)/16777216),256)/2^4),2)*16+MOD(INT(MOD(INT((S6)/16777216),256)/2^5),2)*MOD(INT(MOD(INT((T6)/16777216),256)/2^5),2)*32+MOD(INT(MOD(INT((S6)/16777216),256)/2^6),2)*MOD(INT(MOD(INT((T6)/16777216),256)/2^6),2)*64+MOD(INT(MOD(INT((S6)/16777216),256)/2^7),2)*MOD(INT(MOD(INT((T6)/16777216),256)/2^7),2)*128)*16777216) -> 1296048456 | W6: =MOD(S6+T6-2*V6,4294967296) -> 2997753987 | X6: =((MOD(INT(MOD(INT((W6)/1),256)/2^0),2)*MOD(INT(MOD(INT((U6)/1),256)/2^0),2)*1+MOD(INT(MOD(INT((W6)/1),256)/2^1),2)*MOD(INT(MOD(INT((U6)/1),256)/2^1),2)*2+MOD(INT(MOD(INT((W6)/1),256)/2^2),2)*MOD(INT(MOD(INT((U6)/1),256)/2^2),2)*4+MOD(INT(MOD(INT((W6)/1),256)/2^3),2)*MOD(INT(MOD(INT((U6)/1),256)/2^3),2)*8+MOD(INT(MOD(INT((W6)/1),256)/2^4),2)*MOD(INT(MOD(INT((U6)/1),256)/2^4),2)*16+MOD(INT(MOD(INT((W6)/1),256)/2^5),2)*MOD(INT(MOD(INT((U6)/1),256)/2^5),2)*32+MOD(INT(MOD(INT((W6)/1),256)/2^6),2)*MOD(INT(MOD(INT((U6)/1),256)/2^6),2)*64+MOD(INT(MOD(INT((W6)/1),256)/2^7),2)*MOD(INT(MOD(INT((U6)/1),256)/2^7),2)*128)*1+(MOD(INT(MOD(INT((W6)/256),256)/2^0),2)*MOD(INT(MOD(INT((U6)/256),256)/2^0),2)*1+MOD(INT(MOD(INT((W6)/256),256)/2^1),2)*MOD(INT(MOD(INT((U6)/256),256)/2^1),2)*2+MOD(INT(MOD(INT((W6)/256),256)/2^2),2)*MOD(INT(MOD(INT((U6)/256),256)/2^2),2)*4+MOD(INT(MOD(INT((W6)/256),256)/2^3),2)*MOD(INT(MOD(INT((U6)/256),256)/2^3),2)*8+MOD(INT(MOD(INT((W6)/256),256)/2^4),2)*MOD(INT(MOD(INT((U6)/256),256)/2^4),2)*16+MOD(INT(MOD(INT((W6)/256),256)/2^5),2)*MOD(INT(MOD(INT((U6)/256),256)/2^5),2)*32+MOD(INT(MOD(INT((W6)/256),256)/2^6),2)*MOD(INT(MOD(INT((U6)/256),256)/2^6),2)*64+MOD(INT(MOD(INT((W6)/256),256)/2^7),2)*MOD(INT(MOD(INT((U6)/256),256)/2^7),2)*128)*256+(MOD(INT(MOD(INT((W6)/65536),256)/2^0),2)*MOD(INT(MOD(INT((U6)/65536),256)/2^0),2)*1+MOD(INT(MOD(INT((W6)/65536),256)/2^1),2)*MOD(INT(MOD(INT((U6)/65536),256)/2^1),2)*2+MOD(INT(MOD(INT((W6)/65536),256)/2^2),2)*MOD(INT(MOD(INT((U6)/65536),256)/2^2),2)*4+MOD(INT(MOD(INT((W6)/65536),256)/2^3),2)*MOD(INT(MOD(INT((U6)/65536),256)/2^3),2)*8+MOD(INT(MOD(INT((W6)/65536),256)/2^4),2)*MOD(INT(MOD(INT((U6)/65536),256)/2^4),2)*16+MOD(INT(MOD(INT((W6)/65536),256)/2^5),2)*MOD(INT(MOD(INT((U6)/65536),256)/2^5),2)*32+MOD(INT(MOD(INT((W6)/65536),256)/2^6),2)*MOD(INT(MOD(INT((U6)/65536),256)/2^6),2)*64+MOD(INT(MOD(INT((W6)/65536),256)/2^7),2)*MOD(INT(MOD(INT((U6)/65536),256)/2^7),2)*128)*65536+(MOD(INT(MOD(INT((W6)/16777216),256)/2^0),2)*MOD(INT(MOD(INT((U6)/16777216),256)/2^0),2)*1+MOD(INT(MOD(INT((W6)/16777216),256)/2^1),2)*MOD(INT(MOD(INT((U6)/16777216),256)/2^1),2)*2+MOD(INT(MOD(INT((W6)/16777216),256)/2^2),2)*MOD(INT(MOD(INT((U6)/16777216),256)/2^2),2)*4+MOD(INT(MOD(INT((W6)/16777216),256)/2^3),2)*MOD(INT(MOD(INT((U6)/16777216),256)/2^3),2)*8+MOD(INT(MOD(INT((W6)/16777216),256)/2^4),2)*MOD(INT(MOD(INT((U6)/16777216),256)/2^4),2)*16+MOD(INT(MOD(INT((W6)/16777216),256)/2^5),2)*MOD(INT(MOD(INT((U6)/16777216),256)/2^5),2)*32+MOD(INT(MOD(INT((W6)/16777216),256)/2^6),2)*MOD(INT(MOD(INT((U6)/16777216),256)/2^6),2)*64+MOD(INT(MOD(INT((W6)/16777216),256)/2^7),2)*MOD(INT(MOD(INT((U6)/16777216),256)/2^7),2)*128)*16777216) -> 2183665792 | Y6: =MOD(W6+U6-2*X6,4294967296) -> 898049835 | Z6: =MOD(MOD(C5,2^2)*2^30+INT(C5/2^2),4294967296) -> 3665983897 | AA6: =MOD(MOD(C5,2^13)*2^19+INT(C5/2^13),4294967296) -> 859525199 | AB6: =MOD(MOD(C5,2^22)*2^10+INT(C5/2^22),4294967296) -> 664378792 | AC6: =((MOD(INT(MOD(INT((Z6)/1),256)/2^0),2)*MOD(INT(MOD(INT((AA6)/1),256)/2^0),2)*1+MOD(INT(MOD(INT((Z6)/1),256)/2^1),2)*MOD(INT(MOD(INT((AA6)/1),256)/2^1),2)*2+MOD(INT(MOD(INT((Z6)/1),256)/2^2),2)*MOD(INT(MOD(INT((AA6)/1),256)/2^2),2)*4+MOD(INT(MOD(INT((Z6)/1),256)/2^3),2)*MOD(INT(MOD(INT((AA6)/1),256)/2^3),2)*8+MOD(INT(MOD(INT((Z6)/1),256)/2^4),2)*MOD(INT(MOD(INT((AA6)/1),256)/2^4),2)*16+MOD(INT(MOD(INT((Z6)/1),256)/2^5),2)*MOD(INT(MOD(INT((AA6)/1),256)/2^5),2)*32+MOD(INT(MOD(INT((Z6)/1),256)/2^6),2)*MOD(INT(MOD(INT((AA6)/1),256)/2^6),2)*64+MOD(INT(MOD(INT((Z6)/1),256)/2^7),2)*MOD(INT(MOD(INT((AA6)/1),256)/2^7),2)*128)*1+(MOD(INT(MOD(INT((Z6)/256),256)/2^0),2)*MOD(INT(MOD(INT((AA6)/256),256)/2^0),2)*1+MOD(INT(MOD(INT((Z6)/256),256)/2^1),2)*MOD(INT(MOD(INT((AA6)/256),256)/2^1),2)*2+MOD(INT(MOD(INT((Z6)/256),256)/2^2),2)*MOD(INT(MOD(INT((AA6)/256),256)/2^2),2)*4+MOD(INT(MOD(INT((Z6)/256),256)/2^3),2)*MOD(INT(MOD(INT((AA6)/256),256)/2^3),2)*8+MOD(INT(MOD(INT((Z6)/256),256)/2^4),2)*MOD(INT(MOD(INT((AA6)/256),256)/2^4),2)*16+MOD(INT(MOD(INT((Z6)/256),256)/2^5),2)*MOD(INT(MOD(INT((AA6)/256),256)/2^5),2)*32+MOD(INT(MOD(INT((Z6)/256),256)/2^6),2)*MOD(INT(MOD(INT((AA6)/256),256)/2^6),2)*64+MOD(INT(MOD(INT((Z6)/256),256)/2^7),2)*MOD(INT(MOD(INT((AA6)/256),256)/2^7),2)*128)*256+(MOD(INT(MOD(INT((Z6)/65536),256)/2^0),2)*MOD(INT(MOD(INT((AA6)/65536),256)/2^0),2)*1+MOD(INT(MOD(INT((Z6)/65536),256)/2^1),2)*MOD(INT(MOD(INT((AA6)/65536),256)/2^1),2)*2+MOD(INT(MOD(INT((Z6)/65536),256)/2^2),2)*MOD(INT(MOD(INT((AA6)/65536),256)/2^2),2)*4+MOD(INT(MOD(INT((Z6)/65536),256)/2^3),2)*MOD(INT(MOD(INT((AA6)/65536),256)/2^3),2)*8+MOD(INT(MOD(INT((Z6)/65536),256)/2^4),2)*MOD(INT(MOD(INT((AA6)/65536),256)/2^4),2)*16+MOD(INT(MOD(INT((Z6)/65536),256)/2^5),2)*MOD(INT(MOD(INT((AA6)/65536),256)/2^5),2)*32+MOD(INT(MOD(INT((Z6)/65536),256)/2^6),2)*MOD(INT(MOD(INT((AA6)/65536),256)/2^6),2)*64+MOD(INT(MOD(INT((Z6)/65536),256)/2^7),2)*MOD(INT(MOD(INT((AA6)/65536),256)/2^7),2)*128)*65536+(MOD(INT(MOD(INT((Z6)/16777216),256)/2^0),2)*MOD(INT(MOD(INT((AA6)/16777216),256)/2^0),2)*1+MOD(INT(MOD(INT((Z6)/16777216),256)/2^1),2)*MOD(INT(MOD(INT((AA6)/16777216),256)/2^1),2)*2+MOD(INT(MOD(INT((Z6)/16777216),256)/2^2),2)*MOD(INT(MOD(INT((AA6)/16777216),256)/2^2),2)*4+MOD(INT(MOD(INT((Z6)/16777216),256)/2^3),2)*MOD(INT(MOD(INT((AA6)/16777216),256)/2^3),2)*8+MOD(INT(MOD(INT((Z6)/16777216),256)/2^4),2)*MOD(INT(MOD(INT((AA6)/16777216),256)/2^4),2)*16+MOD(INT(MOD(INT((Z6)/16777216),256)/2^5),2)*MOD(INT(MOD(INT((AA6)/16777216),256)/2^5),2)*32+MOD(INT(MOD(INT((Z6)/16777216),256)/2^6),2)*MOD(INT(MOD(INT((AA6)/16777216),256)/2^6),2)*64+MOD(INT(MOD(INT((Z6)/16777216),256)/2^7),2)*MOD(INT(MOD(INT((AA6)/16777216),256)/2^7),2)*128)*16777216) -> 302141449 | AD6: =MOD(Z6+AA6-2*AC6,4294967296) -> 3921226198 | AE6: =((MOD(INT(MOD(INT((AD6)/1),256)/2^0),2)*MOD(INT(MOD(INT((AB6)/1),256)/2^0),2)*1+MOD(INT(MOD(INT((AD6)/1),256)/2^1),2)*MOD(INT(MOD(INT((AB6)/1),256)/2^1),2)*2+MOD(INT(MOD(INT((AD6)/1),256)/2^2),2)*MOD(INT(MOD(INT((AB6)/1),256)/2^2),2)*4+MOD(INT(MOD(INT((AD6)/1),256)/2^3),2)*MOD(INT(MOD(INT((AB6)/1),256)/2^3),2)*8+MOD(INT(MOD(INT((AD6)/1),256)/2^4),2)*MOD(INT(MOD(INT((AB6)/1),256)/2^4),2)*16+MOD(INT(MOD(INT((AD6)/1),256)/2^5),2)*MOD(INT(MOD(INT((AB6)/1),256)/2^5),2)*32+MOD(INT(MOD(INT((AD6)/1),256)/2^6),2)*MOD(INT(MOD(INT((AB6)/1),256)/2^6),2)*64+MOD(INT(MOD(INT((AD6)/1),256)/2^7),2)*MOD(INT(MOD(INT((AB6)/1),256)/2^7),2)*128)*1+(MOD(INT(MOD(INT((AD6)/256),256)/2^0),2)*MOD(INT(MOD(INT((AB6)/256),256)/2^0),2)*1+MOD(INT(MOD(INT((AD6)/256),256)/2^1),2)*MOD(INT(MOD(INT((AB6)/256),256)/2^1),2)*2+MOD(INT(MOD(INT((AD6)/256),256)/2^2),2)*MOD(INT(MOD(INT((AB6)/256),256)/2^2),2)*4+MOD(INT(MOD(INT((AD6)/256),256)/2^3),2)*MOD(INT(MOD(INT((AB6)/256),256)/2^3),2)*8+MOD(INT(MOD(INT((AD6)/256),256)/2^4),2)*MOD(INT(MOD(INT((AB6)/256),256)/2^4),2)*16+MOD(INT(MOD(INT((AD6)/256),256)/2^5),2)*MOD(INT(MOD(INT((AB6)/256),256)/2^5),2)*32+MOD(INT(MOD(INT((AD6)/256),256)/2^6),2)*MOD(INT(MOD(INT((AB6)/256),256)/2^6),2)*64+MOD(INT(MOD(INT((AD6)/256),256)/2^7),2)*MOD(INT(MOD(INT((AB6)/256),256)/2^7),2)*128)*256+(MOD(INT(MOD(INT((AD6)/65536),256)/2^0),2)*MOD(INT(MOD(INT((AB6)/65536),256)/2^0),2)*1+MOD(INT(MOD(INT((AD6)/65536),256)/2^1),2)*MOD(INT(MOD(INT((AB6)/65536),256)/2^1),2)*2+MOD(INT(MOD(INT((AD6)/65536),256)/2^2),2)*MOD(INT(MOD(INT((AB6)/65536),256)/2^2),2)*4+MOD(INT(MOD(INT((AD6)/65536),256)/2^3),2)*MOD(INT(MOD(INT((AB6)/65536),256)/2^3),2)*8+MOD(INT(MOD(INT((AD6)/65536),256)/2^4),2)*MOD(INT(MOD(INT((AB6)/65536),256)/2^4),2)*16+MOD(INT(MOD(INT((AD6)/65536),256)/2^5),2)*MOD(INT(MOD(INT((AB6)/65536),256)/2^5),2)*32+MOD(INT(MOD(INT((AD6)/65536),256)/2^6),2)*MOD(INT(MOD(INT((AB6)/65536),256)/2^6),2)*64+MOD(INT(MOD(INT((AD6)/65536),256)/2^7),2)*MOD(INT(MOD(INT((AB6)/65536),256)/2^7),2)*128)*65536+(MOD(INT(MOD(INT((AD6)/16777216),256)/2^0),2)*MOD(INT(MOD(INT((AB6)/16777216),256)/2^0),2)*1+MOD(INT(MOD(INT((AD6)/16777216),256)/2^1),2)*MOD(INT(MOD(INT((AB6)/16777216),256)/2^1),2)*2+MOD(INT(MOD(INT((AD6)/16777216),256)/2^2),2)*MOD(INT(MOD(INT((AB6)/16777216),256)/2^2),2)*4+MOD(INT(MOD(INT((AD6)/16777216),256)/2^3),2)*MOD(INT(MOD(INT((AB6)/16777216),256)/2^3),2)*8+MOD(INT(MOD(INT((AD6)/16777216),256)/2^4),2)*MOD(INT(MOD(INT((AB6)/16777216),256)/2^4),2)*16+MOD(INT(MOD(INT((AD6)/16777216),256)/2^5),2)*MOD(INT(MOD(INT((AB6)/16777216),256)/2^5),2)*32+MOD(INT(MOD(INT((AD6)/16777216),256)/2^6),2)*MOD(INT(MOD(INT((AB6)/16777216),256)/2^6),2)*64+MOD(INT(MOD(INT((AD6)/16777216),256)/2^7),2)*MOD(INT(MOD(INT((AB6)/16777216),256)/2^7),2)*128)*16777216) -> 563677568 | AF6: =MOD(AD6+AB6-2*AE6,4294967296) -> 3458249854 | AG6: =MOD(J5+Y6+M6+'📦 SHA-256 Constants'!C4+AN5,4294967296) -> 1541233108 | AH6: =MOD(AF6+R6,4294967296) -> 143694565 | AI6: =AN5 -> 1751477356 | AJ6: ='📦 SHA-256 Constants'!C4 -> 1116352408 | AK6: Round 1 (шаги 1–16) | AM6: 1 | AN6: =(IF(LEN('🔐 SHA-256'!B5)>4,CODE(MID('🔐 SHA-256'!B5,5,1)),IF(LEN('🔐 SHA-256'!B5)=4,128,0)))*16777216+(IF(LEN('🔐 SHA-256'!B5)>5,CODE(MID('🔐 SHA-256'!B5,6,1)),IF(LEN('🔐 SHA-256'!B5)=5,128,0)))*65536+(IF(LEN('🔐 SHA-256'!B5)>6,CODE(MID('🔐 SHA-256'!B5,7,1)),IF(LEN('🔐 SHA-256'!B5)=6,128,0)))*256+(IF(LEN('🔐 SHA-256'!B5)=7,128,0)) -> 1870659584 | AO6: — | AP6: — | AQ6: — | AR6: — | AS6: — | AT6: — | AU6: —
