Workbook

Sheet 🔐 SHA-512
B1: 🔐 SHA-512 — только формулы Excel, без VBA
B2: 64-битная арифметика через hi/lo пары 32-бит · Excel 2013+ · Без макросов
B4: ✏️ ВВЕДИТЕ СЛОВО (1–7 символов ASCII):
B5: hello
B7: 🔑 SHA-512 РЕЗУЛЬТАТ:
B8: ='⚙️ Вычисление'!D2 -> 9b71d224bd62f3785d96d46ad3ea3d73319bfbc2890caadae2dff72519673ca72323c3d99ba5c11d7c7acc6e14b8c5da0c4663475c2e5c3adef46f73bcdec043
B10: 📌 Листы: 📖 Как работает SHA-512 | 📦 Константы | ⚙️ Вычисление
B12: ✅ Верифицировано: "hello" → 9b71d224bd62f3785d96d46ad3ea3d73319bfbc2890caadae2dff72519673ca72323c3d99ba5c11d7c7acc6e14b8c5da0c4663475c2e5c3adef46f73bcdec043
B13: ⚠️ Максимум 7 символов · Только ASCII · Excel 2013+ · Пересчёт ~10–30 сек

Sheet 📖 Как работает SHA-512
B1: 📖 Как работает SHA-512 — пошаговое объяснение
B2: Обзор SHA-512
B3: SHA-512 — криптографическая хэш-функция семейства SHA-2. Блок: 1024 бита (128 байт). Хэш: 512 бит (64 байта = 128 hex символов). 80 раундов (vs 64 у SHA-256). Все операции — над 64-битными словами.
B4: Главное отличие от SHA-256
B5: SHA-256 работает с 32-битными словами (умещаются в double Excel). SHA-512 работает с 64-битными словами (до 2⁶⁴ − 1 = 18 446 744 073 709 551 615). Excel хранит числа как double (точность до 2⁵³). Поэтому каждое 64-битное слово хранится как ПАРА ячеек: hi (старшие 32 бита) и lo (младшие 32 бита). x = hi × 2³² + lo
B6: Арифметика hi/lo
B7: ADD64: lo_result = MOD(a_lo + b_lo, 2³²) carry = INT((a_lo + b_lo) / 2³²) hi_result = MOD(a_hi + b_hi + carry, 2³²) ROTR64(x,n) для n<32: new_hi = MOD( INT(hi/2ⁿ) + MOD(lo,2ⁿ)×2^(32−n), 2³² ) new_lo = MOD( INT(lo/2ⁿ) + MOD(hi,2ⁿ)×2^(32−n), 2³² ) ROTR64(x,n) для n≥32: меняем hi↔lo, затем ROTR(swapped, n−32)
B8: Дополнение (Padding)
B9: После сообщения: байт 0x80, затем нули до позиции 111 (mod 128). Байты 112..127: 128-битная big-endian длина в битах. Для ≤7 байт: итого 128 байт = 16 слов по 64 бита = W[0..15].
B10: Начальные константы H[0..7]
B11: Дробные части квадратных корней первых 8 простых чисел (64-битные): H0 = 0x6a09e667f3bcc908 H1 = 0xbb67ae8584caa73b H2 = 0x3c6ef372fe94f82b H3 = 0xa54ff53a5f1d36f1 H4 = 0x510e527fade682d1 H5 = 0x9b05688c2b3e6c1f H6 = 0x1f83d9abfb41bd6b H7 = 0x5be0cd19137e2179
B12: Расписание сообщения W[0..79]
... B19: · Каждое 64-битное слово = 2 ячейки (hi, lo) · ROTR64, SHR64: чистые MOD/INT формулы (не нужен BITAND!) · XOR64: через AND32 (побайтовое разложение) + a+b−2·AND · AND64: BITAND(hi_a, hi_b) и BITAND(lo_a, lo_b) — по 32 бита каждый · ADD64: MOD + INT для переноса · Каждый из 80 шагов — строка с ~40 вспомогательными ячейками · Расписание W[16..79] — отдельная область на листе ⚙️ Вычисление

Sheet 📦 Константы SHA-512
B1: 📦 SHA-512 Константы K[i] (из кубических корней простых чисел)
B2: K[i] = floor(2⁶⁴ × ∛p[i]) для i=0..79. Хранятся как hi/lo пары: cols C,D = K[i]_hi, K[i]_lo | cols F,G = K[i]_hi hex, K[i]_lo hex
B3: i | C3: K[i] hi (dec) | D3: K[i] lo (dec) | E3: K[i] hex 64 | G3: K[i] hi hex | H3: K[i] lo hex
B4: 0 | C4: 1116352408 | D4: 3609767458 | E4: 428a2f98d728ae22 | G4: 428a2f98 | H4: d728ae22
B5: 1 | C5: 1899447441 | D5: 602891725 | E5: 7137449123ef65cd | G5: 71374491 | H5: 23ef65cd
B6: 2 | C6: 3049323471 | D6: 3964484399 | E6: b5c0fbcfec4d3b2f | G6: b5c0fbcf | H6: ec4d3b2f
B7: 3 | C7: 3921009573 | D7: 2173295548 | E7: e9b5dba58189dbbc | G7: e9b5dba5 | H7: 8189dbbc
B8: 4 | C8: 961987163 | D8: 4081628472 | E8: 3956c25bf348b538 | G8: 3956c25b | H8: f348b538
B9: 5 | C9: 1508970993 | D9: 3053834265 | E9: 59f111f1b605d019 | G9: 59f111f1 | H9: b605d019
B10: 6 | C10: 2453635748 | D10: 2937671579 | E10: 923f82a4af194f9b | G10: 923f82a4 | H10: af194f9b
B11: 7 | C11: 2870763221 | D11: 3664609560 | E11: ab1c5ed5da6d8118 | G11: ab1c5ed5 | H11: da6d8118
B12: 8 | C12: 3624381080 | D12: 2734883394 | E12: d807aa98a3030242 | G12: d807aa98 | H12: a3030242
B13: 9 | C13: 310598401 | D13: 1164996542 | E13: 12835b0145706fbe | G13: 12835b01 | H13: 45706fbe
B14: 10 | C14: 607225278 | D14: 1323610764 | E14: 243185be4ee4b28c | G14: 243185be | H14: 4ee4b28c
B15: 11 | C15: 1426881987 | D15: 3590304994 | E15: 550c7dc3d5ffb4e2 | G15: 550c7dc3 | H15: d5ffb4e2
... B83: 79 | C83: 1816402316 | D83: 1246189591 | E83: 6c44198c4a475817 | G83: 6c44198c | H83: 4a475817

Sheet ⚙️ Вычисление
B1: ⚙️ SHA-512 Вычисление — 80 раундов (64-бит через hi/lo пары)
B2: SHA-512 ХЭШ: | D2: =C90&C91&C92&C93&C94&C95&C96&C97 -> 9b71d224bd62f3785d96d46ad3ea3d73319bfbc2890caadae2dff72519673ca72323c3d99ba5c11d7c7acc6e14b8c5da0c4663475c2e5c3adef46f73bcdec043
B3: Состояние: 8 переменных × 2 ячейки (hi, lo). Колонки C=a_hi D=a_lo E=b_hi F=b_lo G=c_hi H=c_lo I=d_hi J=d_lo K=e_hi L=e_lo M=f_hi N=f_lo O=g_hi P=g_lo Q=h_hi R=h_lo. Вспомогательные колонки S+ — промежуточные XOR/ROTR/AND/ADD.
B4: Шаг | C4: a_hi | D4: a_lo | E4: b_hi | F4: b_lo | G4: c_hi | H4: c_lo | I4: d_hi | J4: d_lo | K4: e_hi | L4: e_lo | M4: f_hi | N4: f_lo | O4: g_hi | P4: g_lo | Q4: h_hi | R4: h_lo | BH4: W[i]_hi | BI4: W[i]_lo
B5: INIT | C5: 1779033703 | D5: 4089235720 | E5: 3144134277 | F5: 2227873595 | G5: 1013904242 | H5: 4271175723 | I5: 2773480762 | J5: 1595750129 | K5: 1359893119 | L5: 2917565137 | M5: 2600822924 | N5: 725511199 | O5: 528734635 | P5: 4215389547 | Q5: 1541459225 | R5: 327033209
